Workbook

Sheet 시작중량_설정
A1: 시작 중량 설정 — 5년 공백 후 복귀
A2: 노란 칸 두 곳만 채우면 각 일차 시트의 웜업 램프와 본세트 중량이 전부 자동 계산됩니다.
A4: 현재 사이클 | C4: 6 | D4: ← 사이클이 끝날 때마다 이 숫자를 1 올리면 일차 시트 중량이 그 사이클에 맞게 갱신됩니다 (1~12)
A6: 종목 | B6: 5년 전 중량 | C6: 권장 시작 (40%) | D6: 시작 중량 ★입력★ | E6: 현재 작업중량 | F6: 본세트
A7: 스쿼트 | B7: 92.5 | C7: =MAX(20,(MROUND(B7*0.4,1)+(MOD(MROUND(B7*0.4,1),5)=4))) -> 37 | D7: 37 | E7: =INDEX(증량기록!$C$10:$C$21,$C$4) -> 62 | F7: 5회 × 5세트
A8: 데드리프트 | B8: 105 | C8: =MAX(20,(MROUND(B8*0.4,1)+(MOD(MROUND(B8*0.4,1),5)=4))) -> 42 | D8: 42 | E8: =INDEX(증량기록!$E$10:$E$21,$C$4) -> 67 | F8: 5회 × 1세트
A9: 벤치프레스 | B9: 47.25 | C9: =MAX(20,(MROUND(B9*0.4,1)+(MOD(MROUND(B9*0.4,1),5)=4))) -> 20 | D9: 23 | E9: =INDEX(증량기록!$G$10:$G$21,$C$4) -> 35 | F9: 5회 × 5세트
A10: 밀리터리 프레스 | B10: 40 | C10: =MAX(20,(MROUND(B10*0.4,1)+(MOD(MROUND(B10*0.4,1),5)=4))) -> 20 | D10: 20 | E10: =INDEX(증량기록!$I$10:$I$21,$C$4) -> 26 | F10: 5회 × 3세트
D11: ↑ 여기에 숫자를 직접 입력
A13: D열(시작 중량)을 바꾸는 법
A14: · D7~D10 노란 칸에 원하는 숫자를 그냥 입력하면 됩니다. 수식이 아니라 일반 숫자입니다.
A15: · 예: 스쿼트를 30kg으로 시작하고 싶으면 D7에 30을 입력. 나머지는 전부 자동으로 따라옵니다.
A16: · C열은 참고용 계산값이므로 건드리지 않아도 됩니다.
A17: · 그리고 C4의 '현재 사이클'은 사이클이 끝날 때마다 1씩 올려주는 칸입니다. 이 두 곳 외에는 손댈 필요가 없습니다.
A19: 5년 공백 후 시작 중량 잡는 법
A20: · 5년 쉬었으면 근력보다 관절 · 건 · 인대와 폼 감각이 먼저 무너져 있다. 근육은 빨리 돌아오지만 이쪽은 느리다.
A21: · 벤치와 프레스는 빈 봉(20kg)에서 시작하는 것이 맞다. 이것이 과한 것이 아니라 정상이다.
A22: · 기준: 10회는 할 수 있을 것 같은 무게로 5회만 하는 것. 여유가 크게 느껴져야 맞다.
A23: · 첫 3~4주는 훈련이 아니라 재적응 기간으로 본다. 가볍다고 느껴도 그대로 간다.
A24: · 너무 가볍게 시작해서 잃는 것은 3~4주뿐이다. 너무 무겁게 시작하면 몇 달을 잃는다.
A26: · 5년 전 중량은 참고치일 뿐 목표가 아니다. 다만 한 번 만들어본 근력은 처음 만들 때보다 빠르게 돌아온다.
... A41: 12사이클 예상 진행 (X 입력이 없을 때)
A42: 사이클 | B42: 스쿼트 | C42: 데드리프트 | D42: 벤치프레스 | E42: 밀리터리 프레스
A43: 1사이클 | B43: =증량기록!C10 -> 37 | C43: =증량기록!E10 -> 42 | D43: =증량기록!G10 -> 23 | E43: =증량기록!I10 -> 20
A44: 2사이클 | B44: =증량기록!C11 -> 42 | C44: =증량기록!E11 -> 47 | D44: =증량기록!G11 -> 25 | E44: =증량기록!I11 -> 21
A45: 3사이클 | B45: =증량기록!C12 -> 47 | C45: =증량기록!E12 -> 52 | D45: =증량기록!G12 -> 27 | E45: =증량기록!I12 -> 22
A46: 4사이클 | B46: =증량기록!C13 -> 52 | C46: =증량기록!E13 -> 57 | D46: =증량기록!G13 -> 30 | E46: =증량기록!I13 -> 23
A47: 5사이클 | B47: =증량기록!C14 -> 57 | C47: =증량기록!E14 -> 62 | D47: =증량기록!G14 -> 32 | E47: =증량기록!I14 -> 25
A48: 6사이클 | B48: =증량기록!C15 -> 62 | C48: =증량기록!E15 -> 67 | D48: =증량기록!G15 -> 35 | E48: =증량기록!I15 -> 26
A49: 7사이클 | B49: =증량기록!C16 -> 67 | C49: =증량기록!E16 -> 72 | D49: =증량기록!G16 -> 37 | E49: =증량기록!I16 -> 27
A50: 8사이클 | B50: =증량기록!C17 -> 72 | C50: =증량기록!E17 -> 77 | D50: =증량기록!G17 -> 40 | E50: =증량기록!I17 -> 28
A51: 9사이클 | B51: =증량기록!C18 -> 77 | C51: =증량기록!E18 -> 82 | D51: =증량기록!G18 -> 42 | E51: =증량기록!I18 -> 30
A52: 10사이클 | B52: =증량기록!C19 -> 82 | C52: =증량기록!E19 -> 87 | D52: =증량기록!G19 -> 45 | E52: =증량기록!I19 -> 31
A53: 11사이클 | B53: =증량기록!C20 -> 87 | C53: =증량기록!E20 -> 92 | D53: =증량기록!G20 -> 47 | E53: =증량기록!I20 -> 32
A54: 12사이클 | B54: =증량기록!C21 -> 92 | C54: =증량기록!E21 -> 97 | D54: =증량기록!G21 -> 50 | E54: =증량기록!I21 -> 33
A56: · 위 표는 X 입력이 없다고 가정한 계획선이다. 실제 진행은 증량기록 시트가 결정한다.
A58: 복귀 운용 — 날짜로 자동 계산 (2026-09-13 신설 · 09-13 기준 정정)
A59: 프로그램 시작일 | C59: 46237 | D59: ← 1주차가 시작된 월요일. 주차는 월요일에 넘어간다. 주차는 세는 숫자일 뿐 중량과 무관하다
A60: 사이클 기준일 | C60: 46279 | D60: ← 아래 '기준 사이클'이 시작된 월요일. 여기서부터 2주마다 한 칸씩 올라간다
A61: 기준 사이클 | C61: 6 | D61: ← 사이클 기준일에 시작된 사이클 번호. '현재 사이클'(C4)과 같은 번호로 둔다
...

Sheet 주간계획
A1: 운동 프로그램 — 10일 주기 (A블록 4일 · 휴식 · B블록 4일 · 휴식)
A2: 적용 시기: 재택 근무 기간 (~9월) | 10일 주기 / 1일 1세션 | 1사이클부터 설계 볼륨 100% (볼륨램프 해제) | 요일이 아니라 주기 안의 순서로 돈다
A4: 일차 | B4: 내용 | C4: 메인 리프트 | D4: 주요 근육군 | E4: 세트 | F4: 예상 시간
A5: 1 | B5: 당기기 A (수직) | C5: — | D5: 광배 · 승모(중부) · 기립근 · 복부 | E5: =INDEX(D1_당기기A!$E:$E,MATCH("세트 합계",D1_당기기A!$D:$D,0)) -> 32 | F5: ="약 "&INDEX(D1_당기기A!$I:$I,MATCH("세트 합계",D1_당기기A!$D:$D,0))&"분" -> 약 76분
A6: 2 | B6: 밀기 A (수평) | C6: 벤치프레스 5×5 | D6: 흉근 · 측면삼각 · 후면삼각 · 삼두 | E6: =INDEX(D2_밀기A!$E:$E,MATCH("세트 합계",D2_밀기A!$D:$D,0)) -> 28 | F6: ="약 "&INDEX(D2_밀기A!$I:$I,MATCH("세트 합계",D2_밀기A!$D:$D,0))&"분" -> 약 71분
A7: 3 | B7: 하체 A (무릎) | C7: 스쿼트 5×5 | D7: 대퇴사두 · 햄스트링 · 둔근 | E7: =INDEX(D3_하체A!$E:$E,MATCH("세트 합계",D3_하체A!$D:$D,0)) -> 26 | F7: ="약 "&INDEX(D3_하체A!$I:$I,MATCH("세트 합계",D3_하체A!$D:$D,0))&"분" -> 약 71분
A8: 4 | B8: 어깨·팔 A | C8: — | D8: 삼각근(측면·후면) · 승모(하부) · 흉근(인클라인 스미스 · 펙덱) · 이두 · 전완 · 종아리 | E8: =INDEX(D4_어깨팔A!$E:$E,MATCH("세트 합계",D4_어깨팔A!$D:$D,0)) -> 36 | F8: ="약 "&INDEX(D4_어깨팔A!$I:$I,MATCH("세트 합계",D4_어깨팔A!$D:$D,0))&"분" -> 약 73분
A9: 5 | B9: 휴식 | C9: — | D9: — | E9: 0 | F9: —
A10: 6 | B10: 당기기 B (수평) | C10: — | D10: 광배 · 능형근 · 승모(중부·상부) · 이두 · 기립근 · 중둔근 · 종아리 | E10: =INDEX(D6_당기기B!$E:$E,MATCH("세트 합계",D6_당기기B!$D:$D,0)) -> 28 | F10: ="약 "&INDEX(D6_당기기B!$I:$I,MATCH("세트 합계",D6_당기기B!$D:$D,0))&"분" -> 약 70분
A11: 7 | B11: 밀기 B (수직) | C11: 밀리터리 3×5 | D11: 삼각근 · 흉근(상부 · 디클라인 플라이) · 승모(하부) · 복부 | E11: =INDEX(D7_밀기B!$E:$E,MATCH("세트 합계",D7_밀기B!$D:$D,0)) -> 30 | F11: ="약 "&INDEX(D7_밀기B!$I:$I,MATCH("세트 합계",D7_밀기B!$D:$D,0))&"분" -> 약 73분
A12: 8 | B12: 하체 B (고관절) | C12: 데드리프트 1×5 + 백오프 2×5 | D12: 둔근 · 햄스트링 · 대퇴사두 | E12: =INDEX(D8_하체B!$E:$E,MATCH("세트 합계",D8_하체B!$D:$D,0)) -> 24 | F12: ="약 "&INDEX(D8_하체B!$I:$I,MATCH("세트 합계",D8_하체B!$D:$D,0))&"분" -> 약 74분
A13: 9 | B13: 어깨·팔 B | C13: — | D13: 삼각근(측면·후면·전면) · 승모(하부) · 흉근(상부 플라이) · 삼두 · 이두 · 전완 · 내전근 · 중둔근 | E13: =INDEX(D9_어깨팔B!$E:$E,MATCH("세트 합계",D9_어깨팔B!$D:$D,0)) -> 36 | F13: ="약 "&INDEX(D9_어깨팔B!$I:$I,MATCH("세트 합계",D9_어깨팔B!$D:$D,0))&"분" -> 약 70분
A14: 10 | B14: 휴식 | C14: — | D14: — | E14: 0 | F14: —
A15: 합계 | E15: =SUM(E5:E14) -> 240 | F15: ="약 "&(INDEX(D1_당기기A!$I:$I,MATCH("세트 합계",D1_당기기A!$D:$D,0))+INDEX(D2_밀기A!$I:$I,MATCH("세트 합계",D2_밀기A!$D:$D,0))+INDEX(D3_하체A!$I:$I,MATCH("세트 합계",D3_하체A!$D:$D,0))+INDEX(D4_어깨팔A!$I:$I,MATCH("세트 합계",D4_어깨팔A!$D:$D,0))+INDEX(D6_당기기B!$I:$I,MATCH("세트 합계",D6_당기기B!$D:$D,0))+INDEX(D7_밀기B!$I:$I,MATCH("세트 합계",D7_밀기B!$D:$D,0))+INDEX(D8_하체B!$I:$I,MATCH("세트 합계",D8_하체B!$D:$D,0))+INDEX(D9_어깨팔B!$I:$I,MATCH("세트 합계",D9_어깨팔B!$D:$D,0)))&"분 ("&INT((INDEX(D1_당기기A!$I:$I,MATCH("세트 합계",D1_당기기A!$D:$D,0))+INDEX(D2_밀기A!$I:$I,MATCH("세트 합계",D2_밀기A!$D:$D,0))+INDEX(D3_하체A!$I:$I,MATCH("세트 합계",D3_하체A!$D:$D,0))+INDEX(D4_어깨팔A!$I:$I,MATCH("세트 합계",D4_어깨팔A!$D:$D,0))+INDEX(D6_당기기B!$I:$I,MATCH("세트 합계",D6_당기기B!$D:$D,0))+INDEX(D7_밀기B!$I:$I,MATCH("세트 합계",D7_밀기B!$D:$D,0))+INDEX(D8_하체B!$I:$I,MATCH("세트 합계",D8_하체B!$D:$D,0))+INDEX(D9_어깨팔B!$I:$I,MATCH("세트 합계",D9_어깨팔B!$D:$D,0)))/60)&"시간 "&MOD((INDEX(D1_당기기A!$I:$I,MATCH("세트 합계",D1_당기기A!$D:$D,0))+INDEX(D2_밀기A!$I:$I,MATCH("세트 합계",D2_밀기A!$D:$D,0))+INDEX(D3_하체A!$I:$I,MATCH("세트 합계",D3_하체A!$D:$D,0))+INDEX(D4_어깨팔A!$I:$I,MATCH("세트 합계",D4_어깨팔A!$D:$D,0))+INDEX(D6_당기기B!$I:$I,MATCH("세트 합계",D6_당기기B!$D:$D,0))+INDEX(D7_밀기B!$I:$I,MATCH("세트 합계",D7_밀기B!$D:$D,0))+INDEX(D8_하체B!$I:$I,MATCH("세트 합계",D8_하체B!$D:$D,0))+INDEX(D9_어깨팔B!$I:$I,MATCH("세트 합계",D9_어깨팔B!$D:$D,0))),60)&"분)" -> 약 578분 (9시간 38분)
A17: 배치 논리
A18: · 10일 주기다. 1~4일차 A블록 · 5일차 완전휴식 · 6~9일차 B블록 · 10일차 완전휴식 · 다시 1일차. 네 패턴(당기기 · 밀기 · 하체 · 어깨팔)이 각각 A/B로 5일 간격.
A19: · 무거운 하체일 뒤가 둘 다 저부하다: 3일차 스쿼트 → 4일차 어깨·팔 A → 5일차 완전휴식, 8일차 데드 → 9일차 어깨·팔 B → 10일차 완전휴식. 어깨·팔 날은 척추 부하가 0이다.
A20: · 부위 간격이 5일로 완전히 균등하다 — 짝수 주기라 가능하다. 9일에서는 4일과 5일이 번갈아 왔다. 벤치(2) ↔ 밀리터리(7) · 스쿼트(3) ↔ 데드(8) · 당기기(1) ↔ (6) · 어깨·팔(4) ↔ (9).
A21: · 4·9일차 어깨·팔은 척추 부하 0인 고립일이다 — 33~38세트라 가벼운 날은 아니다. 다음 세션에 영향이 있으면 무게가 과한 것 — 세트가 아니라 무게를 내린다.
A22: · 연속 훈련은 최대 4일(1~4 · 6~9)이고 각 블록 4일째가 고립 세션이라 체감은 3일 → 가벼움 → 휴식이다.
A23: · 당기기 A(수직) / B(수평), 밀기 A(수평) / B(수직), 하체 A(무릎) / B(고관절), 어깨·팔 A / B. 같은 부위를 5일 뒤 다른 각도로 친다.
A24: · 기립근: 데드(8일차) + 덤벨 RDL(1일차). RDL은 20kg으로 가볍게 — 척추 부하가 아니라 자세 유지가 목적.
A26: 10일 주기로 바꾸며 (2026-09-04 전환)
A27: · 4훈련 · 휴식 · 4훈련 · 휴식. 어깨(옛 8일차 40세트)를 다른 세 패턴처럼 A/B로 나눠 4 · 9일차에 두고, 1 · 2 · 5 · 6일차의 삼두 · 이두 · 전완을 그쪽으로 옮겼다. 종목 12개 이동, 세트는 한 개도 안 늘고 안 줄었다 — 239 그대로.
A28: · 세션이 24~38세트 · 67~73분으로 고르게 됐다. 9일 주기에서는 1일차 38 · 6일차 34(84분) · 8일차 40이었고 80분 넘는 날이 셋이었다. 이제 없다.
A29: · 시간 균등화(같은 날 추가): 디클라인 플라이(2일차) · 펙덱(7일차) → 4일차, 케이블 힙 외전(8일차) → 9일차, 스탠딩 카프(3일차) → 6일차. 4종목 13세트, 총량 불변. 분할 직후 57~80분이던 편차를 67~73분으로 좁혔다 — 남은 6분은 종목 하나 크기라 세트를 쪼개지 않는 한 더 못 좁힌다. 흉근이 2·4·7일차 셋으로 흩어졌고 종아리는 (1,6) 거울이 됐다.
... A101: · 9일차는 드롭 0 — 36세트로 이미 꽉 찬 날이다. 측면은 2일차 레터럴에 더해 4일차 머신 레터럴에도 붙였다(사용자 선택, 둘 다 +60초). 이두는 프리쳐 컬 한 곳(9일차 인클라인 컬은 이틀 뒤 친업), 머신 숄더 프레스는 제외(전면 삼각근은 프레스 4종으로 충분), 시티드 카프·트랩바 슈러그·흉근 상부(케이블 플라이 교체 필요)는 보류.

Sheet D1_당기기A
A1: 1일차 — 당기기 A (수직)
A2: 광배 위쪽 · 견갑골 하강 · 전완 · 삼두. 6일차 당기기 B(수평)와 각도를 나눈다.
A3: 웜업 — 스캡 풀업 2세트 × 5~8 (세트 카운트 제외): 팔은 편 채 견갑골만 하강, 여유 있게(실패 4회+ 전 종료). 친업 직전 견갑 하강 프라이밍.
A4: 운동 구성
A5: # | B5: 종목 | C5: 근육군 | D5: 중량(Kg) | E5: 세트 | F5: 횟수 | G5: 수행(초) | H5: 휴식(초) | I5: 종목 분 | J5: 간접 자극 | K5: 메모 | L5: 대체 종목 | M5: 세트별 휴식(초) | N5: 슈퍼세트 | O5: 드롭(초)
A6: 1 | B6: 친업 (어시스트 가능) | C6: 광배 | D6: 60 | E6: 4 | F6: 6~8 | G6: 35 | H6: 155 | I6: =IF(E6=0,0,ROUND((E6*(G6+H6)+O6)/60,1)) -> 12.7 | J6: 이두 | K6: 수직 당기기 메인. 광배 위쪽 섬유 비중이 큼 | L6: 어시스트 풀업 머신 (개수가 안 나올 때) / 뉴트럴 그립 친업 (팔꿈치가 편함) / 랫풀다운 | M6: 135/145/160/180
A7: 2 | B7: 랫풀다운 | C7: 광배 | D7: 40 | E7: 3 | F7: 8~12 | G7: 40 | H7: 120 | I7: =IF(E7=0,0,ROUND((E7*(G7+H7)+O7)/60,1)) -> 8 | J7: 이두 | K7: 친업 뒤에 무게 조절 수단으로. 그립을 친업과 다르게 (친업이 언더면 여기선 오버) [2026-09-05 4→2] 뒤 2세트를 원암 랫풀다운으로 나눴다 (사용자 요청). | L7: 뉴트럴 그립 랫풀다운 / 원암 랫풀다운 (좌우 독립) / 케이블 풀오버 (이두 개입 최소)
A8: 3 | B8: 원암 랫풀다운 | C8: 광배 | D8: 20 | E8: 2 | F8: 8~12 (좌우) | G8: 80 | H8: 120 | I8: =IF(E8=0,0,ROUND((E8*(G8+H8)+O8)/60,1)) -> 8.7 | J8: 이두 | K8: [2026-09-05 신설] 랫풀다운 4세트를 양팔 2 + 원암 2로 나눴다 (사용자 요청). 하이 풀리에 D핸들을 걸고 뉴트럴 그립으로 한 팔씩 — 좌우를 따로 세니 약한 쪽이 강한 쪽에 묻히지 않고, 당기는 쪽으로 몸통을 살짝 기울여 광배를 더 늘린 자리에서 시작할 수 있다. 팔꿈치를 옆구리 쪽으로 끌어내리고 맨 아래에서 1초 정지. 세트 수는 좌우 한 번씩을 1세트로 센다(수행 80초 = 40초 × 2). 무게는 양팔의 절반에서 시작해 약한 쪽 기준으로 올린다. 광배 직접 세트는 이 날 8 그대로. [2026-09-07 마지막 세트 드롭 2단 — 실패 뒤 쉬지 않고 20~30% 내려 두 번. 한쪽을 끝까지 내려간 뒤 반대쪽. 팔로 당기기 시작하면 그 자리에서 끝. 세트 수 그대로, 증량 판정은 첫 세트로만. +120초는 O열] | L8: 원암 케이블 풀다운 (다른 하이 풀리) / 원암 덤벨 로우 (풀다운 기구가 찼을 때) / 뉴트럴 그립 랫풀다운 4세트로 합치기 | O8: 120
A9: 4 | B9: 바벨 로우(스미스)(그립 넓게) | C9: 승모(중부)·능형근 | D9: 맨몸 | E9: 4 | F9: 8~10 | G9: 40 | H9: 120 | I9: =IF(E9=0,0,ROUND((E9*(G9+H9)+O9)/60,1)) -> 10.7 | J9: 전거근 | K9: 그립을 어깨너비보다 넓게 — 팔꿈치를 45~90°로 벌려 견갑골을 모으는 종목이다. 주동근은 능형근·중부승모이고 광배는 협력근으로 계상한다(간접 0.5). 팔꿈치를 몸통에 붙여 당기면 광배 종목이 되어 같은 날 친업·랫풀다운과 겹친다 — 그러라고 넣은 자리가 아니다. [2026-09-04 라벨 정정: 광배 → 승모(중부)·능형근. 세트 수는 그대로 4] | L9: 스캡 랫풀다운 (앉아서) / 어시스트 풀업 머신에서 스캡 풀업 / 바에 매달려 정지 3초
A10: 5 | B10: 페이스풀(로프) | C10: 승모(중부)·능형근 | D10: 12.5 | E10: 3 | F10: 12~15 | G10: 45 | H10: 60 | I10: =IF(E10=0,0,ROUND((E10*(G10+H10)+O10)/60,1)) -> 5.3 | J10: 삼각근(후면) · 외회전근 | K10: 수평 후인 + 외회전. 랫풀다운과 같은 케이블 스테이션에서 높이만 올려 이어서 한다. 팔꿈치를 어깨 높이로 유지하고 마지막에 손등이 뒤로 돌아갈 때까지 외회전을 끝낼 것 — 외회전을 빼면 그냥 후면삼각 종목이 되어 6일차와 겹친다. 무게 욕심 내면 승모 상부가 다 가져간다. 수직 당기기 날이지만 승모 중부 사이클당 2회(6일차와 5일 간격)를 만들기 위한 배치이며, 10~15kg으로 가벼워 친업·랫풀다운의 광배 자극과 경쟁하지 않는다. 덤벨 RDL과 같은 성격의 예외 배치. | L10: 로프 페이스풀 (1순위) / 밴드 페이스풀 (케이블 자리가 없을 때) / 리버스 펙덱을 팔 편 채로 + 케이블 외회전 별도 (외회전 성분을 분리 수행)
A11: 6 | B11: 바벨 컬 | C11: 이두 | D11: 30~35 | E11: 0 | F11: 8~12 | G11: 40 | H11: 70 | I11: =IF(E11=0,0,ROUND((E11*(G11+H11)+O11)/60,1)) -> 0 | J11: 전완 | K11: [2026-08-28 — 이 종목은 2일차 밀기 A로 옮겨 3세트로 되살아났다. 당기기 날은 친업·랫풀다운으로 이두가 이미 간접 3.5세트분 지친 뒤라 컬을 두기에 나쁜 자리였다. 이 행은 기록으로만 남긴다] | L11: EZ바 컬 (손목이 편함) / 케이블 컬 (전 구간 장력) / 해머 컬 (상완요골근 동시)
A12: 7 | B12: 라잉 레그 레이즈 | C12: 복부 | D12: 맨몸 | E12: 4 | F12: 12~15 | G12: 40 | H12: 60 | I12: =IF(E12=0,0,ROUND((E12*(G12+H12)+O12)/60,1)) -> 6.7 | K12: 복부 굴곡(하부). 바닥에 누워 다리를 모은 채 들어올린다 — 허리가 뜨면 장요근 종목이 되므로 손을 엉덩이 밑에 받쳐 골반을 후방경사로 고정하고, 내릴 때 발이 바닥에 닿기 전에 멈춰 장력을 유지한다. 6일차 중량 크런치(상부)와 굴곡 축을 나눈다. [2026-09-02 — 변형 4가지 서킷에서 일반 라잉 레그 레이즈로 환원. 세트당 100회·150초라 4세트가 14분으로 이 세션에서 가장 긴 종목이었고, 변형마다 자극 부위가 흩어져 하부 굴곡 한 축에 집중되지 않았다. 종목 분 14.0 → 6.7] | L12: 캡틴 체어 레그 레이즈 (그립·허리 부담 없음 — 1순위) / 행잉 레그 레이즈 (가장 어렵다, 그립이 먼저 나감) / 리버스 크런치 (골반을 말아 올려 하부 집중) / 라잉 레그 레이즈 변형 4가지 https://www.youtube.com/watch?v=BGaOGtfTKPc
A13: 8 | B13: 케이블 트렁크 로테이션 | C13: 복부 | D13: 10~15 | E13: 3 | F13: 12~15 (좌우) | G13: 70 | H13: 60 | I13: =IF(E13=0,0,ROUND((E13*(G13+H13)+O13)/60,1)) -> 6.5 | K13: [2026-09-04 신설] 복부의 네 번째 축 — 회전. 그동안 굴곡(상·하)과 항신전만 있고 회전은 통째로 비어 있었다. **뒷발 뒤꿈치를 돌려 골반이 상체를 따라가게 한다** — 골반을 고정한 채 돌리면 회전이 요추 하나에 몰린다(앉아서 하는 트렁크 로테이션 머신을 안 쓰는 이유가 이것이다). **팔은 고정하고 몸통으로 돌린다** — 팔로 당기면 어깨 운동이 된다. 무게는 가볍게, 통제되는 범위에서. 6일차 중량 크런치를 6→3으로 내리며 이쪽으로 옮겨온 자리다. 왜 1일차인가 — 10일차 휴식 다음 날이라 척추가 가장 신선하다. 9일차는 데드(8일차) 다음 날이고 "척추 부하 0"이 그 날의 설계 근거라 회전을 얹지 않았다. | L13: 케이블 우드촙 (하이 투 로우) / 팔로프 프레스 (항회전) / 밴드 트렁크 로테이션
A14: 9 | B14: 카프 레이즈 (스탠딩) | C14: 종아리 | D14: 10 | E14: 3 | F14: 12~15 | G14: 40 | H14: 75 | I14: =IF(E14=0,0,ROUND((E14*(G14+H14)+O14)/60,1)) -> 5.8 | K14: [2026-09-04 신설] 종아리를 성장 구간(주당 10)으로 올리려고 3일차·8일차에 이어 세 번째 자리를 만들었다. 무릎 편 상태라 비복근 쪽. 당기기 날에 둔 이유는 하체날 두 곳이 이미 가장 긴 세션이라 더 얹지 않기로 해서다 — 종아리는 고립이라 어느 날에 있든 상관없다. | L14: 레그 프레스 카프 (기계가 비었을 때) / 스미스 카프 레이즈
A15: 10 | B15: 덤벨 루마니안 데드리프트 | C15: 기립근 | D15: 20 | E15: 3 | F15: 12 | G15: 45 | H15: 90 | I15: =IF(E15=0,0,ROUND((E15*(G15+H15)+O15)/60,1)) -> 6.8 | J15: 둔근·햄스트링 | K15: 기립근 보조. 20kg으로 가볍게 — 무게를 올리면 햄스트링 종목이 되고 척추 부하도 같이 올라간다. 데드(8일차)와 이틀 간격이라 이 자리가 맞다 [2026-09-04 3→6→3] 백 익스텐션이 없던 동안 기립근을 늘릴 수단이 이것뿐이라 6으로 올렸다가, 기구를 쓸 수 있다는 확인을 받고 3으로 되돌렸다. 힌지를 두 배로 하는 것보다 기립근 전용 종목을 따로 두는 편이 척추 부하도 낮고 자극도 곧다. [2026-09-04 순서 변경: 백 익스텐션과 자리를 맞바꿔 10번이 됐다] | L15: 케이블 풀스루 (척추 압박 최소) / 굿모닝 (빈 봉~40kg, 가볍게) / 45도 하이퍼익스텐션 벤치 (있는 경우) / 스티프 레그드 데드리프트. 어느 쪽이든 가볍게 — 성장이 아니라 자세 유지가 목적
A16: 11 | B16: 백 익스텐션 (45도) | C16: 기립근 | D16: 맨몸 | E16: 3 | F16: 12~15 | G16: 40 | H16: 60 | I16: =IF(E16=0,0,ROUND((E16*(G16+H16)+O16)/60,1)) -> 5 | K16: [2026-09-04 순서 변경] 기구가 옆 체육관에 있어 세션 맨 마지막으로 내렸다 — 본 체육관 일을 전부 끝내고 이동한다. 앞으로 종목을 추가할 때 이 뒤에 붙이지 말 것. 45도 백 익스텐션, 이 프로그램의 원래 설계 종목이었는데 기구를 못 써서 덤벨 RDL로 대체해 뒀던 것을 되돌렸다. **척추 신전을 강조해서 한다** — 등을 편 채 고관절만 접는 힌지식으로 하면 둔근·햄스트링이 주동근이 되고 기립근은 버티기만 한다. 옆 체육관까지 갔는데 그러면 헛걸음이다. | L16: 원판 5~10kg 안고 (맨몸이 쉬워지면) / 굿모닝(스미스) / 덤벨 루마니안 데드리프트
D17: 세트 합계 | E17: =SUM(E6:E16) -> 32 | I17: =ROUND(SUM(I6:I16),0) -> 76
A19: 변경 (2026-09-05)
A20: · 랫풀다운 4 → 양팔 2 + 원암 2 (사용자 요청). 3번 원암 랫풀다운을 새로 두고 뒤 종목 번호가 하나씩 밀렸다. 광배 직접 세트는 8 그대로 · 31세트 · 약 72분.
A22: 드롭 세트 (2026-09-07)
A23: · 원암 랫풀다운 마지막 세트에 드롭 2단, +120초 (사용자 요청). 편측이라 한쪽을 끝까지 내려간 뒤 반대쪽으로 넘어간다 — 번갈아 하면 쉬는 시간이 생겨 드롭 효과가 약해진다. 광배는 주당 12.4로 낮고 예산은 잠겨 있어, 세트 수를 안 늘리고 자극만 얹는 자리다.
A24: · O열 '드롭(초)'는 마지막 세트에 더해지는 시간이다. I열 종목 분에 합산되고, 앱 타이머는 마지막 세트를 그만큼 늘린 뒤 '드롭세트'라고 읊는다. E열 세트 수와 세트검산은 건드리지 않는다.

Sheet D2_밀기A
A1: 2일차 — 밀기 A (수평)
A2: 벤치 5×5가 이 프로그램의 최우선 종목. 7일차 밀기 B(수직)와 각도를 나눈다. 삼두 푸쉬다운을 마지막에 둔다 — 프레스로 지친 삼두를 고립으로 마무리한다 (2026-09-05, 4일차에서 이동). [이력] 바벨 컬은 2026-09-04에 4일차로 갔다.
A4: 메인: 벤치프레스
A5: 중량(Kg) | B5: 반복 | C5: 세트
A6: =MAX(20,(MROUND(시작중량_설정!$E$9*0.4,1)+(MOD(MROUND(시작중량_설정!$E$9*0.4,1),5)=4))) -> 20 | B6: 5 | C6: 2
A7: =IF(MAX(20,(MROUND(시작중량_설정!$E$9*0.6,1)+(MOD(MROUND(시작중량_설정!$E$9*0.6,1),5)=4)))<=MAX(20,(MROUND(시작중량_설정!$E$9*0.4,1)+(MOD(MROUND(시작중량_설정!$E$9*0.4,1),5)=4))),"생략",MAX(20,(MROUND(시작중량_설정!$E$9*0.6,1)+(MOD(MROUND(시작중량_설정!$E$9*0.6,1),5)=4)))) -> 21 | B7: 5 | C7: 1
A8: =IF(MAX(20,(MROUND(시작중량_설정!$E$9*0.75,1)+(MOD(MROUND(시작중량_설정!$E$9*0.75,1),5)=4)))<=MAX(20,(MROUND(시작중량_설정!$E$9*0.6,1)+(MOD(MROUND(시작중량_설정!$E$9*0.6,1),5)=4))),"생략",MAX(20,(MROUND(시작중량_설정!$E$9*0.75,1)+(MOD(MROUND(시작중량_설정!$E$9*0.75,1),5)=4)))) -> 26 | B8: 3 | C8: 1
A9: =IF(MAX(20,(MROUND(시작중량_설정!$E$9*0.9,1)+(MOD(MROUND(시작중량_설정!$E$9*0.9,1),5)=4)))<=MAX(20,(MROUND(시작중량_설정!$E$9*0.75,1)+(MOD(MROUND(시작중량_설정!$E$9*0.75,1),5)=4))),"생략",MAX(20,(MROUND(시작중량_설정!$E$9*0.9,1)+(MOD(MROUND(시작중량_설정!$E$9*0.9,1),5)=4)))) -> 32 | B9: 2 | C9: 1
A10: =시작중량_설정!$E$9 -> 35 | B10: 5 | C10: 5
A11: ↑ '시작중량_설정'과 자동 연동. 20 = 빈 봉. '생략'은 앞 세트와 중량이 겹쳐 불필요하다는 뜻.
A13: 웜업 — 회전근개 (세트 카운트 제외)
A14: · 케이블 외회전 2세트 × 12~15회. 팔꿈치 90도로 접어 옆구리에 붙이고 바깥으로만 회전.
A15: · 매우 가볍게 — 2.5~5kg. 무거우면 광배와 후면 삼각근이 대신 일하며 목적을 잃는다.
A16: · 근비대 항목이 아니라 관절 준비 항목이므로 세트 합계에 넣지 않는다.
A18: 운동 구성
A19: # | B19: 종목 | C19: 근육군 | D19: 중량(Kg) | E19: 세트 | F19: 횟수 | G19: 수행(초) | H19: 휴식(초) | I19: 종목 분 | J19: 간접 자극 | K19: 메모 | L19: 대체 종목 | M19: 세트별 휴식(초) | N19: 슈퍼세트 | O19: 드롭(초)
A20: 1 | B20: 벤치프레스 (본세트) | C20: 흉근(중하부) | D20: =시작중량_설정!$E$9 -> 35 | E20: 5 | F20: 5 | G20: 30 | H20: 180 | I20: =IF(E20=0,0,ROUND((E20*(G20+H20)+O20)/60,1)) -> 17.5 | J20: 삼두·전면삼각 | K20: 현재 최우선 종목. 사이클당 2.25kg 마이크로로딩. 여기가 무너지면 그 사이클 나머지를 줄인다 | L20: 스미스 벤치프레스 (궤도 고정) / 체스트 프레스 머신 / 플로어 프레스 (어깨가 아플 때) | M20: 150/165/180/195/210
A21: 2 | B21: 딥스 | C21: 흉근(중하부) | D21: 70 10개 채움 | E21: 4 | F21: 8~10 | G21: 40 | H21: 155 | I21: =IF(E21=0,0,ROUND((E21*(G21+H21)+O21)/60,1)) -> 13 | J21: 삼두 | K21: 상체 앞으로 기울여 흉근 비중 확보. 쉬워지면 벨트로 중량 추가 | L21: 어시스트 딥스 머신 / 디클라인 덤벨 프레스 / 체스트 딥스 머신 https://www.youtube.com/shorts/1tQQKeAMwr0 | M21: 135/145/160/180
A22: 3 | B22: 인클라인 덤벨 플라이(혹은 벡덱플라이 머신으로) | C22: 흉근(상부) | D22: 8 | E22: 4 | F22: 10~12 | G22: 40 | H22: 105 | I22: =IF(E22=0,0,ROUND((E22*(G22+H22)+O22)/60,1)) -> 9.7 | K22: 프레싱 뒤 고립. 늘어난 구간에서 멈추지 말고 부드럽게 [2026-09-04 4→7] 흉근 상부 보강(주당 7.0 → 10.1). 7일차 인클라인 머신과 함께 사이클당 2회. [2026-09-04 7→4] 같은 날 인클라인 벤치프레스(스미스) 3세트를 새로 두면서 나눴다. 흉근 상부 직접 합계는 그대로다. | L22: 케이블 크로스오버 (아래→위) / 펙덱 플라이 (등받이를 눕혀 인클라인 각으로) / 인클라인 머신 플라이
A23: 4 | B23: 레터럴 레이즈 | C23: 삼각근(측면) | D23: 6 | E23: 6 | F23: 12~15 | G23: 40 | H23: 70 | I23: =IF(E23=0,0,ROUND((E23*(G23+H23)+O23)/60,1)) -> 12 | K23: 덤벨은 아래 구간에 저항이 안 걸린다 — 원암 케이블(7일차)이 그 구간을 메운다 [2026-09-07 마지막 세트 드롭 2단 — 실패 뒤 쉬지 않고 20~30% 내려 두 번. 무거운 구간에서 승모가 끼면 내린 무게로 어깨만 마저 채운다. 세트 수 그대로, 증량 판정은 앞 세트로만. +60초는 O열] | L23: 케이블 레터럴 레이즈 (전 구간 장력) / 레터럴 레이즈 머신 / 라잉 레터럴 | O23: 60
A24: 5 | B24: 리버스 펙덱플라이 | C24: 삼각근(후면) | D24: 20 | E24: 5 | F24: 12~15 | G24: 40 | H24: 70 | I24: =IF(E24=0,0,ROUND((E24*(G24+H24)+O24)/60,1)) -> 10.2 | K24: [2026-09-07 마지막 세트 드롭 2단 — 실패 뒤 쉬지 않고 핀 20~30% 내려 두 번. 세트 수 그대로, 증량 판정은 앞 세트로만. +60초는 O열] | L24: https://www.youtube.com/shorts/Et70PVUQpDE | O24: 60
A25: 6 | B25: 케이블 푸쉬다운 (로프) | C25: 삼두 | D25: 20 | E25: 4 | F25: 10~15 | G25: 40 | H25: 70 | I25: =IF(E25=0,0,ROUND((E25*(G25+H25)+O25)/60,1)) -> 8.3 | K25: [2026-09-05 4일차 → 2일차 이동] 벤치·딥스·플라이·레이즈를 다 마친 뒤 마지막에 — 프레스에서 이미 지친 삼두를 고립으로 마무리하는 자리다. 4일차에 있을 때의 근거였던 '삼두가 안 쓰인 날의 신선함'은 포기했고, 대신 밀기 날에 삼두가 같이 끝난다. 로프로 마지막에 손등을 바깥으로 벌리면 외측두가 끝까지 수축한다. 팔꿈치는 옆구리에 고정 — 어깨로 누르면 광배 종목이 된다. 9일차 라잉 익스텐션이 늘어난 구간(장두)이라 여기는 짧아진 구간(외측두·내측두)으로 축을 나눈다. 삼두 직접은 2일차 4 · 9일차 4로 사이클당 2회 그대로. [2026-08-28 — 원래 1일차 인클라인 덤벨 컬 자리에 들어왔던 종목] [2026-09-07 마지막 세트 드롭 2단 — 실패 뒤 쉬지 않고 핀 20~30% 내려 두 번. 팔꿈치는 끝까지 옆구리에. 세트 수 그대로, 증량 판정은 앞 세트로만. +60초는 O열] | L25: V바 푸쉬다운 (손목이 편함) / 오버헤드 케이블 익스텐션 (장두 — 7일차와 겹치므로 차선) / 덤벨 킥백 / 벤치 딥스 (케이블이 없을 때) | O25: 60
D26: 세트 합계 | E26: =SUM(E20:E25) -> 28 | I26: =ROUND(SUM(I20:I25),0) -> 71
A27: 드롭 세트 (2026-09-07)
A28: · 레터럴 레이즈 · 리버스 펙덱 · 푸쉬다운 마지막 세트에 드롭 2단, 각 +60초 (사용자 요청). 벤치 뒤라 셋이 몰려도 메인에 영향이 없다. 20~30%씩 내려 쉬지 않고 두 번, 세 번째부터는 피로만 쌓인다.
A29: · O열 '드롭(초)'는 마지막 세트에 더해지는 시간이다. I열 종목 분에 합산되고, 앱 타이머는 마지막 세트를 그만큼 늘린 뒤 '드롭세트'라고 읊는다. E열 세트 수와 세트검산은 건드리지 않는다.

Sheet D3_하체A
A1: 3일차 — 하체 A (무릎 지배)
A2: 스쿼트 · 레그프레스 중심. 8일차 하체 B(고관절 지배)와 5일 간격.
A4: 메인: 스쿼트
A5: 중량(Kg) | B5: 반복 | C5: 세트
A6: =MAX(20,(MROUND(시작중량_설정!$E$7*0.4,1)+(MOD(MROUND(시작중량_설정!$E$7*0.4,1),5)=4))) -> 25 | B6: 5 | C6: 2
A7: =IF(MAX(20,(MROUND(시작중량_설정!$E$7*0.6,1)+(MOD(MROUND(시작중량_설정!$E$7*0.6,1),5)=4)))<=MAX(20,(MROUND(시작중량_설정!$E$7*0.4,1)+(MOD(MROUND(시작중량_설정!$E$7*0.4,1),5)=4))),"생략",MAX(20,(MROUND(시작중량_설정!$E$7*0.6,1)+(MOD(MROUND(시작중량_설정!$E$7*0.6,1),5)=4)))) -> 37 | B7: 5 | C7: 1
A8: =IF(MAX(20,(MROUND(시작중량_설정!$E$7*0.75,1)+(MOD(MROUND(시작중량_설정!$E$7*0.75,1),5)=4)))<=MAX(20,(MROUND(시작중량_설정!$E$7*0.6,1)+(MOD(MROUND(시작중량_설정!$E$7*0.6,1),5)=4))),"생략",MAX(20,(MROUND(시작중량_설정!$E$7*0.75,1)+(MOD(MROUND(시작중량_설정!$E$7*0.75,1),5)=4)))) -> 47 | B8: 3 | C8: 1
A9: =IF(MAX(20,(MROUND(시작중량_설정!$E$7*0.9,1)+(MOD(MROUND(시작중량_설정!$E$7*0.9,1),5)=4)))<=MAX(20,(MROUND(시작중량_설정!$E$7*0.75,1)+(MOD(MROUND(시작중량_설정!$E$7*0.75,1),5)=4))),"생략",MAX(20,(MROUND(시작중량_설정!$E$7*0.9,1)+(MOD(MROUND(시작중량_설정!$E$7*0.9,1),5)=4)))) -> 56 | B9: 2 | C9: 1
A10: =시작중량_설정!$E$7 -> 62 | B10: 5 | C10: 5
A11: ↑ '시작중량_설정'과 자동 연동. 20 = 빈 봉. '생략'은 앞 세트와 중량이 겹쳐 불필요하다는 뜻.
A13: 운동 구성
A14: # | B14: 종목 | C14: 근육군 | D14: 중량(Kg) | E14: 세트 | F14: 횟수 | G14: 수행(초) | H14: 휴식(초) | I14: 종목 분 | J14: 간접 자극 | K14: 메모 | L14: 대체 종목 | M14: 세트별 휴식(초) | N14: 슈퍼세트 | O14: 드롭(초)
A15: 1 | B15: 스쿼트 (본세트) | C15: 대퇴사두 | D15: =시작중량_설정!$E$7 -> 62 | E15: 5 | F15: 5 | G15: 35 | H15: 193 | I15: =IF(E15=0,0,ROUND((E15*(G15+H15)+O15)/60,1)) -> 19 | J15: 둔근·기립근 | K15: 무릎 지배 메인. 데드(8일차)와 5일 간격이라 기립근이 회복된 상태에서 친다 | L15: 스미스 스쿼트 / 핵 스쿼트 (대퇴사두 집중) / 프론트 스쿼트 / 벨트 스쿼트 (척추 부하 없음) | M15: 150/170/190/215/240
A16: 2 | B16: 레그 프레스 | C16: 대퇴사두 | D16: 120 | E16: 3 | F16: 8~12 | G16: 45 | H16: 150 | I16: =IF(E16=0,0,ROUND((E16*(G16+H16)+O16)/60,1)) -> 9.8 | J16: 둔근 | K16: 수/토 3+3 분할. 궤도 고정이라 대퇴사두가 확실히 한계까지 간다. 발판 위치는 중간 | L16: 핵 스쿼트 / 레그 익스텐션 (완전 고립) / 프론트 스쿼트
A17: 3 | B17: 불가리안 스플릿 스쿼트 | C17: 둔근 | D17: 맨몸 | E17: 3 | F17: 10 (좌우) | G17: 90 | H17: 150 | I17: =IF(E17=0,0,ROUND((E17*(G17+H17)+O17)/60,1)) -> 12 | J17: 대퇴사두·중둔근 | K17: 한 다리 지지라 관상면 안정화가 함께 들어온다 | L17: 덤벨 런지 / 워킹 런지 / 스텝업 / 리버스 런지 (무릎 부담 ↓)
A18: 4 | B18: 레그 컬 | C18: 햄스트링 | D18: 40 | E18: 4 | F18: 10~12 | G18: 40 | H18: 120 | I18: =IF(E18=0,0,ROUND((E18*(G18+H18)+O18)/60,1)) -> 11.9 | K18: 무릎 굴곡. 8일차 RDL(고관절 신전)과 기능이 다르다 — 둘 다 필요 [2026-09-07 마지막 세트 드롭 2단 — 실패 뒤 쉬지 않고 핀 20~30% 내려 두 번. 지친 햄스트링은 수축 위치에서 쥐가 잘 나니 위에서 멈추지 말고 바로 내린다. 다음 햄스트링은 8일차, 5일 뒤. 세트 수 그대로, 증량 판정은 앞 세트로만. +75초는 O열] | L18: 라잉 레그 컬 · 시티드 레그 컬 (시티드가 늘어난 구간을 더 씀) / 노르딕 햄 컬 | O18: 75
A19: 5 | B19: 이너 타이 | C19: 내전근 | D19: 35 | E19: 4 | F19: 12~15 | G19: 40 | H19: 10 | I19: =IF(E19=0,0,ROUND((E19*(G19+H19)+O19)/60,1)) -> 3.3 | K19: 내전근 직접 종목은 이것뿐. 스쿼트·레그프레스·불가리안이 간접 5.5를 채워 주므로 실질은 이미 하한 위다. [2026-09-04 — 아우터 타이와 슈퍼세트로 묶었다. 겸용 머신이라 패드만 뒤집으면 되어 전환이 10초다. 휴식 105 → 10초는 그 전환 시간이고, 라운드 간 휴식은 아우터 쪽 105초가 맡는다. 길항근 쌍이라 서로의 피로를 나눠 갖지 않으며, 각 근육 입장에서는 자기 세트 간격이 오히려 155초로 늘어난다] | L19: 와이드 스탠스 레그 프레스 / 코사크 스쿼트 / 케이블 힙 내전 | N19: A
A20: 6 | B20: 아우터 타이 (힙 외전) | C20: 중둔근 | D20: 30~35 | E20: 4 | F20: 12~15 | G20: 40 | H20: 105 | I20: =IF(E20=0,0,ROUND((E20*(G20+H20)+O20)/60,1)) -> 9.7 | K20: 관상면 외전. [2026-09-04 부활 — v18에서 8일차로 보냈던 자리를 이너 타이와의 슈퍼세트로 되살렸다. 중둔근이 직접 3 · 간접 1.0으로 주당 환산 3.5, 프로그램 최하위였다. 여기 4세트로 주당 7.0 · 사이클당 2회(3일차·8일차, 간격 4일)가 된다. 8일차 케이블 힙 외전은 그대로 둔다 — 앉아서 고관절 굽힌 채(여기)와 서서 편 채(8일차)는 각도가 다르다. 반드시 양측 동시 머신으로 — 케이블 좌우 버전은 수행 80초라 40초짜리 이너와 라운드가 안 맞는다] | L20: 힙 어브덕션 머신 (겸용 머신이 없을 때) / 케이블 힙 외전 (좌우 — 슈퍼세트로는 부적합) / 밴드 몬스터 워크 / 사이드 라잉 힙 외전 | N20: A
A21: 7 | B21: 앱휠 롤아웃 | C21: 복부 | D21: 맨몸 | E21: 3 | F21: 10 | G21: 40 | H21: 60 | I21: =IF(E21=0,0,ROUND((E21*(G21+H21)+O21)/60,1)) -> 5 | K21: 항신전. 다음날이 당기기 B라 브레이싱 손실이 문제되지 않는다 | L21: 애브 롤아웃 / 사이드 플랭크 / 팔로프 프레스 (항회전)
D22: 세트 합계 | E22: =SUM(E15:E21) -> 26 | I22: =ROUND(SUM(I15:I21),0) -> 71
A23: 드롭 세트 (2026-09-07)
A24: · 레그 컬 마지막 세트에 드롭 2단, +75초 (사용자 요청). 핀 스택 단관절이고 그날 햄스트링 마지막 종목이다. 다음 햄스트링은 8일차 RDL, 5일 뒤. 3일차 뒤는 4일차 고립·5일차 휴식이라 회복이 겹치지 않는다. 지친 햄스트링은 수축 위치에서 쥐가 나기 쉬우니 드롭 반복은 위에서 멈추지 않는다.
A25: · O열 '드롭(초)'는 마지막 세트에 더해지는 시간이다. I열 종목 분에 합산되고, 앱 타이머는 마지막 세트를 그만큼 늘린 뒤 '드롭세트'라고 읊는다. E열 세트 수와 세트검산은 건드리지 않는다.

Sheet D4_어깨팔A
A1: 4일차 — 어깨·팔 A
A2: 측면·후면 삼각근 + 승모 하부 + 흉근(인클라인 스미스 · 펙덱) + 이두 · 전완 + 종아리. 약 71분. 4-1-4-1 전환으로 신설 — 옛 8일차 어깨 세션의 절반과 1·2일차의 팔이 여기로 왔다. 거울 슬롯은 9일차 어깨·팔 B. [2026-09-05] 이너·아우터 타이·리스트 컬은 9일차로, 디클라인 플라이는 7일차로, 시티드 카프는 6일차로 갔고, 9일차의 리버스 리스트 컬·리버스컬과 6일차 스탠딩 카프·오버헤드 슈러그가 왔다. 펙덱·머신 레터럴 마지막 세트 드롭 +2분 — 약 73분 (2026-09-07).
A3: 웜업 — 케이블 외회전 2세트 × 12~15 (세트 카운트 제외): 매우 가볍게 2.5~5kg. 팔꿈치를 90도로 접어 옆구리에 붙이고 바깥으로만 회전. 대체: 밴드 외회전 / 아주 가벼운 페이스풀.
A4: 운동 구성
A5: # | B5: 종목 | C5: 근육군 | D5: 중량(Kg) | E5: 세트 | F5: 횟수 | G5: 수행(초) | H5: 휴식(초) | I5: 종목 분 | J5: 간접 자극 | K5: 메모 | L5: 대체 종목 | M5: 세트별 휴식(초) | N5: 슈퍼세트 | O5: 드롭(초)
A6: 1 | B6: 머신 레터럴 레이즈 | C6: 삼각근(측면) | D6: 10 | E6: 3 | F6: 12~15 | G6: 40 | H6: 70 | I6: =IF(E6=0,0,ROUND((E6*(G6+H6)+O6)/60,1)) -> 6.5 | K6: 궤도가 고정돼 반동이 안 들어간다. 중간 구간을 끝까지 쓴다. 어깨가 으쓱 따라 올라가면 승모가 대신 일하는 것 — 무게를 내린다. [2026-09-07 마지막 세트 드롭 2단 — 실패 뒤 쉬지 않고 핀 20~30% 내려 두 번. 측면 두 번째 드롭 자리(2일차 레터럴과 이틀 간격, 사용자 선택). 세트 수 그대로, 증량 판정은 앞 세트로만. +60초는 O열] | L6: 덤벨 레터럴 (머신 없을 때 — 몸 옆이 아니라 살짝 앞) / 케이블 레터럴 양팔 크로스 | O6: 60
A7: 2 | B7: 와이드 그립 케이블 업라이트 로우 | C7: 삼각근(측면) | D7: 15 | E7: 3 | F7: 12~15 | G7: 40 | H7: 75 | I7: =IF(E7=0,0,ROUND((E7*(G7+H7)+O7)/60,1)) -> 5.8 | J7: 승모(상부) | K7: 레이즈 계열과 달리 팔꿈치를 굽힌 채 당기는 궤적이라 측면의 다른 섬유가 동원되고, 승모 상부가 같이 온다 (승모 상부는 사이클당 3세트로 하한 미달이라 이 겸용이 값을 한다). 그립은 어깨너비보다 넓게, 팔꿈치는 가슴 높이까지만 — 좁은 그립으로 턱까지 올리면 견봉하 공간이 좁아진다. | L7: EZ바 와이드 업라이트 로우 / 스미스 업라이트 로우 / 케이블 Y 레이즈 (충돌이 느껴질 때)
A8: 3 | B8: 케이블 리버스 플라이 | C8: 삼각근(후면) | D8: 12~15 | E8: 3 | F8: 12~15 | G8: 40 | H8: 70 | I8: =IF(E8=0,0,ROUND((E8*(G8+H8)+O8)/60,1)) -> 5.5 | J8: 중부승모·능형근 | K8: 팔을 편 채 수평으로만 벌린다. 케이블이라 수축 지점에서도 장력이 유지된다. 팔꿈치가 어깨선을 크게 지나가면 후면 삼각근에서 능형근으로 넘어간다. | L8: 리버스 펙덱 (2일차와 같은 머신이면 그립만 바꿔 각도를 나눈다) / 벤트오버 케이블 크로스
A9: 4 | B9: 리어 델트 로우 (로프) | C9: 삼각근(후면) | D9: 20 | E9: 3 | F9: 12~15 | G9: 40 | H9: 80 | I9: =IF(E9=0,0,ROUND((E9*(G9+H9)+O9)/60,1)) -> 6 | J9: 중부승모·능형근 | K9: 팔꿈치를 어깨 높이로 벌린 채 당긴다. 4·5번이 팔을 편 수평 외전이라면 이쪽은 굽힌 채 당기기라 모멘트암과 동원 섬유가 다르다 — 한 세션에 후면 9세트를 넣으면서 자극이 겹치지 않게 하는 축이 이것이다. 팔꿈치가 몸통 옆으로 붙으면 광배 로우가 된다. | L9: 와이드 그립 시티드 케이블 로우 (팔꿈치 벌려) / 페이스풀 (외회전까지 포함) / 머신 로우 와이드 그립
A10: 5 | B10: 오버헤드 슈러그(스미스) | C10: 승모(하부) | D10: 20 | E10: 3 | F10: 12~15 | G10: 40 | H10: 60 | I10: =IF(E10=0,0,ROUND((E10*(G10+H10)+O10)/60,1)) -> 5 | K10: [2026-09-05 6일차 → 4일차 이동] 6·7일차 이틀 연속이던 승모 하부를 4·7·9일차(3/2/5일)로 폈다. 스미스에서 하므로 바로 뒤 인클라인 스미스와 같은 기구 — 벤치만 넣으면 된다. [2026-09-04 신설] 승모 하부는 실질 4.5로 가장 크게 모자랐다. 7일차에 같은 종목이 3세트 있었지만 사이클당 1회뿐이었고, 여기와 9일차를 더해 3회로 만들었다. 견갑 상방회전 — 팔을 머리 위에 둔 채 으쓱한다. | L10: 오버헤드 케이블 슈러그 / 프론 Y 레이즈
A11: 6 | B11: 인클라인 벤치프레스(스미스) | C11: 흉근(상부) | D11: 30 | E11: 3 | F11: 8~12 | G11: 40 | H11: 150 | I11: =IF(E11=0,0,ROUND((E11*(G11+H11)+O11)/60,1)) -> 9.5 | J11: 삼두 · 삼각근(전면) | K11: [2026-09-05 2일차 → 4일차 이동] 이 날 유일한 프레스라 벤치·딥스 뒤 세 번째로 치던 때보다 신선하다 — 중량을 2일차 시절보다 올려 잡아도 된다. 레이즈 6세트 뒤에 두는 이유는 9일차 머신 숄더 프레스와 같다: 앞에 두면 프레스 피로로 레이즈 중량이 눌린다. 복합관절이라 뒤의 플라이 두 종목 앞이다. [2026-09-04 신설 당시] 흉근 상부 7세트를 플라이 하나로 채우던 것을 프레스 3 + 플라이 4로 나눴다. 플라이는 늘어난 구간에서 벌리는 자극, 프레스는 중량을 실을 수 있는 축 — 상부 흉근을 한 종류로만 때리지 않는다. 2일차 인클라인 플라이 · 7일차 인클라인 머신과 함께 흉근 상부 사이클당 3회. | L11: 인클라인 바벨 벤치프레스 / 인클라인 덤벨 프레스 / 인클라인 벤치프레스 머신
A12: 7 | B12: 펙덱 플라이 | C12: 흉근(중하부) | D12: 25~30 | E12: 3 | F12: 10~12 | G12: 40 | H12: 90 | I12: =IF(E12=0,0,ROUND((E12*(G12+H12)+O12)/60,1)) -> 7.5 | J12: 삼각근(전면) | K12: [2026-09-04 신설] 프레싱 두 종목을 끝내고 고립으로 마무리하는 자리. 팔꿈치 각도를 고정한 채 어깨 수평 내전만 — 굽혔다 펴면 프레스가 된다. 첫날은 25kg으로 10~12회가 실패 2~3회 안에 들어오는지 보고 맞춘다. 이 종목을 넣어 흉근 합산이 주당 환산 24.1이 됐다(천장 20 초과) — 사용자가 알고 선택한 것이며, 세트 질이 떨어지면 2일차 디클라인 케이블 플라이 3세트를 먼저 뺀다. [2026-09-07 마지막 세트 드롭 2단 — 실패 뒤 쉬지 않고 핀 20~30% 내려 두 번. 세트 수 그대로, 증량 판정은 앞 세트로만. +60초는 O열] | L12: 케이블 크로스오버 / 플랫 벤치 덤벨 플라이 (가동범위 ↑) / 머신 체스트 플라이 | O12: 60
A13: 8 | B13: 바벨 컬 | C13: 이두 | D13: 20~25 | E13: 3 | F13: 8~12 | G13: 40 | H13: 70 | I13: =IF(E13=0,0,ROUND((E13*(G13+H13)+O13)/60,1)) -> 5.5 | J13: 전완 | K13: 밀기 날에 이두를 넣는 이유는 1일차 푸쉬다운과 같다 — 이 세션에서 이두는 전혀 안 쓰이므로 완전히 신선하다. 이두 직접이 6 → 9세트, 사이클당 2회 → 3회가 된다 (2일차 · 6일차 · 9일차, 간격 3-3-2일). 6일차 프리쳐(반동 차단 · 짧아진 구간) · 9일차 인클라인(늘어난 구간)과 달리 여기는 선 자세 전 구간이라 무게를 가장 많이 건다. 반동 쓰지 말 것 — 상체를 뒤로 젖히면 이두가 아니라 기립근 종목이 된다. 팔꿈치는 몸통 옆에 고정. [2026-08-28 추가 — 1일차에 0세트로 접혀 있던 종목을 이 자리로 되살린 것] | L13: EZ바 컬 (손목이 편함) / 케이블 바 컬 (전 구간 장력 유지) / 머신 컬 / 덤벨 컬 양팔 동시
A14: 9 | B14: 리버스 리스트익스텐션 컬(손등 아래) | C14: 전완 | D14: 15 | E14: 4 | F14: 15 | G14: 40 | H14: 60 | I14: =IF(E14=0,0,ROUND((E14*(G14+H14)+O14)/60,1)) -> 6.7 | K14: [2026-09-05 9일차 → 4일차 이동] 신근(리스트 컬 손등 위)은 9일차로 가서 대항쌍이 날을 나눠 갖는다. 전완 4일차 8 · 9일차 3. 손목 굴근. 1일차 리버스와 대항쌍 [v17 감량 4→3 — 전완 실질 8로 자체 하한 유지] | L14: 덤벨 리스트 컬 (한 손씩) / 케이블 리스트 컬 / 비하인드백 리스트 컬
A15: 10 | B15: 리버스컬 | C15: 전완 | D15: 15 | E15: 4 | F15: 10~15 | G15: 40 | H15: 70 | I15: =IF(E15=0,0,ROUND((E15*(G15+H15)+O15)/60,1)) -> 7.3 | J15: 이두(상완근) | K15: [2026-09-05 9일차 → 4일차 이동] 바벨 컬(뒤침) 바로 뒤에 엎침 그립으로 — 같은 굴곡 패턴을 다른 축으로. 오버핸드(엎침) 그립 컬 — 상완요골근·상완근이 주동이다. 언더핸드 프리쳐 컬(#5)과 그립을 나눠 같은 굴곡 패턴을 다른 축으로 친다. 손목은 중립으로 고정하고 반동 금지 — 손목을 위로 꺾으면 리스트 컬(#6)이 되고 상완요골근에서 빠진다. 회외가 없어 이두가 짧아진 자리에서 힘을 못 쓰므로 언더핸드 컬보다 30~40% 가벼운 것이 정상이다. #7 자리인 이유: 그립을 쓰는 종목이라 컬 계열 바로 뒤에 붙이고, 스트랩을 쓰는 트랩바 슈러그를 뒤로 보낸다. [2026-08-28 추가 — 전완 직접 6→9세트] | L15: EZ바 리버스 컬 (손목 부담 ↓ — 1순위) / 케이블 리버스 컬 (수축 지점까지 장력 유지 · 핀 단위 미세 증량) / 리버스 프리쳐 컬 (반동 차단) / 해머 컬 (중립 그립 — 상완요골근 같은 계열이나 자극 각도가 다르다)
A16: 11 | B16: 카프 레이즈 (스탠딩) | C16: 종아리 | D16: 10 | E16: 4 | F16: 12~15 | G16: 40 | H16: 75 | I16: =IF(E16=0,0,ROUND((E16*(G16+H16)+O16)/60,1)) -> 7.7 | K16: [2026-09-05 6일차 → 4일차 이동] 6일차 자리를 힙 외전에 내주고 왔다. 종아리 1·4·8일차(3일/4일/3일). 같은 날 시티드 카프 2세트와 비복근·가자미근으로 나뉜다. 무릎 편 상태 — 비복근 주도. 8일차 시티드(가자미근)와 역할이 다르다 | L16: 스탠딩 카프 레이즈 머신 / 레그 프레스 발판 끝에서 / 스미스 카프 레이즈
D17: 세트 합계 | E17: =SUM(E6:E16) -> 36 | I17: =ROUND(SUM(I6:I16),0) -> 73
F18: 랫풀다운 3세트/ 그립 변경 3세트 추가
A19: 4일차 원칙
A20: · 2026-09-04 4-1-4-1 전환으로 신설. 옛 8일차 어깨 40세트를 A/B로 나누고 1·2일차에서 삼두 · 이두 · 전완을 가져왔다. 세트는 한 개도 안 늘었다 — 총량 예산 239 안에서 자리만 옮긴 것이다.
A21: · 시간 균등화(같은 날)로 흉근 플라이 2종(디클라인 케이블 · 펙덱)이 2·7일차에서 왔다. 벤치 이틀 뒤 고립 6세트 — 흉근이 2·4·7일차 셋으로 흩어진다. "볼륨을 여러 날로 흩는 쪽이 낫지만 자리가 없었다"던 그 자리가 생긴 것이다.
A22: · 3일차 스쿼트 다음 날이자 5일차 휴식 앞. 척추 부하 0 — 이 자리에 있는 이유다.
A23: · 실패지점 1~2회 남기고 멈춘다. 세트 간 휴식 60~80초. 메인 리프트 없음 — 볼륨을 채우는 날이지 무게를 올리는 날이 아니다.
A24: · 측면 · 후면 · 이두 · 전완이 9일차와 5일 간격으로 두 번 온다. [2026-09-05] 삼두 푸쉬다운은 2일차(벤치 날 마지막)로 갔다 — 삼두 직접은 2일차 4 · 9일차 4, 간격 7일/3일로 비대칭이 됐다. 대신 이 날 인클라인 스미스 4세트가 벤치 이틀 뒤 두 번째 프레스로 온다.
A25: · 바벨 컬은 2일차 밀기에서 왔다. "당기기 뒤 지친 이두를 피한다"는 원래 이유는 팔 전용일이 생기며 해소됐고, 2일차는 82분 → 76분으로 시간 상한 안에 들어왔다.
A26: · 이너·아우터 타이는 겸용 머신 슈퍼세트(A). 3일차와 같은 방식이고, 옛 8일차에서 그대로 옮겨 왔다.
A27: 되돌리는 법 [2026-09-05 9일차로 이동]
A28: · E열을 0으로 내리면 회색으로 접히고 합계 · 세트검산에서 빠진다. 다만 그 세트는 예산에서 사라지는 게 아니라 어딘가로 돌아가야 한다 — 잔여 예산이 양수로 뜨면 그 신호다.
A30: 이동 (2026-09-05)
A31: · 이너·아우터 타이 슈퍼세트와 리스트 컬(손등 위)이 9일차로, 디클라인 케이블 플라이가 7일차로 갔다. 9일차에서 리버스 리스트 컬·리버스컬·시티드 카프가 왔다. 31세트 · 약 62분 — 스쿼트 다음 날인 이 날에서 하체 고립을 뺀 것이라 가장 가벼운 날이 됐다. 척추 부하 0은 그대로.
... A38: · 머신 레터럴 레이즈 마지막 세트에도 드롭 2단, +60초 (사용자 선택, 2026-09-07 추가). 측면 두 번째 자리 — 2일차 레터럴과 이틀 간격이지만 측면은 회복이 빠르다. 4일차 드롭은 둘, 약 73분.

Sheet D6_당기기B
A1: 6일차 — 당기기 B (수평)
A2: 로우 · 견갑골 후인 · 이두 · 전완. 1일차 당기기 A(수직)와 각도를 나눈다. [2026-09-05] 스탠딩 카프는 4일차로, 중량 크런치는 7일차로 갔고 9일차 케이블 힙 외전이 왔다. 약 72분. 오버헤드 슈러그는 4일차로 가고 4일차 시티드 카프 2세트가 왔다 — 약 71분. 원암 로우·프리쳐 컬·스캡 슈러그 마지막 세트 드롭 +4분 — 약 76분 (2026-09-07).
A3: 웜업 — 밴드 풀 어파트 2세트 × 15 (세트 카운트 제외): 가볍게, 견갑골 후인 프라이밍. 대체: 케이블 스캡 로우 / 아주 가벼운 페이스풀.
A4: 운동 구성
A5: # | B5: 종목 | C5: 근육군 | D5: 중량(Kg) | E5: 세트 | F5: 횟수 | G5: 수행(초) | H5: 휴식(초) | I5: 종목 분 | J5: 간접 자극 | K5: 메모 | L5: 대체 종목 | M5: 세트별 휴식(초) | N5: 슈퍼세트 | O5: 드롭(초)
A6: 1 | B6: 해머 스트랭스 로우(오버그립) | C6: 승모(중부)·능형근 | D6: 45 | E6: 4 | F6: 8~10 | G6: 40 | H6: 150 | I6: =IF(E6=0,0,ROUND((E6*(G6+H6)+O6)/60,1)) -> 12.7 | J6: 중부승모·이두 | K6: 수평 당기기 메인. 가슴이 받쳐져 허리 부담이 없다. 그립은 넓게 · 팔꿈치는 벌려서 — 견갑 후인이 주동이라 능형근·중부승모로 계상하고 광배는 협력근이다(간접 0.5). [2026-09-04 라벨 정정: 광배 → 승모(중부)·능형근. 세트 수는 그대로 4] | L6: 체스트 서포티드 로우 / 티바 로우 / 펜들레이 로우 (척추 부하 ↑) / 바벨 로우
A7: 2 | B7: 시티드 케이블 로우 | C7: 광배 | D7: 47 | E7: 2 | F7: 8~12 | G7: 40 | H7: 150 | I7: =IF(E7=0,0,ROUND((E7*(G7+H7)+O7)/60,1)) -> 6.3 | J7: 중부승모·이두 | K7: 해머 로우와 역할을 나눈다 — 해머는 넓은 그립·팔꿈치 벌려 상부등, 이쪽은 좁은 그립·팔꿈치 붙여 광배. 이 날 광배 직접 종목은 이것과 3번 원암 로우뿐이다. [2026-09-05 5→3] 뒤 2세트를 원암 케이블 로우로 나눴다 (사용자 요청). | L7: 원암 케이블 로우 (좌우 독립) / 덤벨 로우 / 머신 로우
A8: 3 | B8: 원암 케이블 로우 | C8: 광배 | D8: 20 | E8: 2 | F8: 8~12 (좌우) | G8: 80 | H8: 150 | I8: =IF(E8=0,0,ROUND((E8*(G8+H8)+O8)/60,1)) -> 9.7 | J8: 중부승모·이두 | K8: [2026-09-05 신설] 시티드 케이블 로우 5세트를 양팔 3 + 원암 2로 나눴다 (사용자 요청). 같은 로우 스테이션에서 바를 D핸들로 바꿔 한 팔씩 — 팔꿈치를 몸통에 붙이고, 당기는 쪽으로 몸통을 살짝 돌려 광배 수축을 끝까지 가져간다(반대 손은 기구를 잡아 몸통을 고정). 좌우를 따로 세니 약한 쪽이 강한 쪽에 묻히지 않는다. 세트 수는 좌우 한 번씩을 1세트로 센다(수행 80초 = 40초 × 2). 무게는 양팔의 절반에서 시작해 약한 쪽 기준으로 올린다. 광배 직접 세트는 이 날 5 그대로. 4번 스캡 슈러그는 이 뒤에 바를 다시 걸고 이어서 한다. [2026-09-07 마지막 세트 드롭 2단 — 실패 뒤 쉬지 않고 20~30% 내려 두 번. 한쪽을 끝까지 내려간 뒤 반대쪽. 몸통이 돌아가거나 팔로 당기기 시작하면 그 자리에서 끝. 세트 수 그대로, 증량 판정은 첫 세트로만. +120초는 O열] | L8: 원암 덤벨 로우 (벤치 지지) / 원암 머신 로우 (해머 스트랭스 한 팔씩) / 시티드 케이블 로우 5세트로 합치기 | O8: 120
A9: 4 | B9: 시티드 케이블 로우 스캡 슈러그(두번째 크기 바) | C9: 승모(중부)·능형근 | D9: 32 | E9: 4 | F9: 12~15 | G9: 40 | H9: 60 | I9: =IF(E9=0,0,ROUND((E9*(G9+H9)+O9)/60,1)) -> 7.7 | J9: 후면 삼각근 | K9: 2번 시티드 케이블 로우와 같은 스테이션 — 3번 원암 로우 뒤에 바를 다시 걸고 무게만 내려 이어서 한다 (자리 이동 없음). 팔꿈치 각도를 세트 내내 고정하고 견갑골만 뒤로 — 가동범위 2~3cm, 모은 자리에서 1초 정지. 상체를 뒤로 눕히면 하부 승모 각도가 되고, 팔을 당기면 광배로 넘어간다. 케이블이라 수축 지점에서도 장력이 유지되고 핀 단위 미세 증량이 된다 (플레이트 로드 머신은 이 무게대에서 계단이 너무 큼). [2026-09-07 마지막 세트 드롭 2단 — 실패 뒤 쉬지 않고 핀 20~30% 내려 두 번. 지치면 팔로 당겨 로우가 되는데 그래도 등 상부라 손해가 작다. 세트 수 그대로, 증량 판정은 앞 세트로만. +60초는 O열] | L9: 해머 스트랭스 로우에서 팔 편 채 견갑골만 — 가슴 패드가 상체를 고정해줘 자세 잡기는 더 쉬우나 무게 미세 조정이 어렵다 / 리버스 펙덱을 팔 편 채로 / 켈소 슈러그 (받침 벤치가 있을 때) | O9: 60
A10: 5 | B10: 케이블 리버스 플라이 | C10: 삼각근(후면) | D10: 12~15 | E10: 0 | F10: 12 | G10: 40 | H10: 70 | I10: =IF(E10=0,0,ROUND((E10*(G10+H10)+O10)/60,1)) -> 0 | J10: 중부승모·능형근 | K10: 후면 삼각근은 프레스로 자라지 않는다 — 반드시 별도로 센다 [v17 제외 — 후면은 2일차 4 · 7일차 3 · 9일차 9로 사이클당 3회 16세트 — 이 행은 그 재편으로 비워둔 자리다] | L10: 리버스 펙덱 (자세 유지가 쉬워 사실상 상위 호환) / 페이스풀 / 인클라인 벤치 리어델트 레이즈
A11: 6 | B11: 프리쳐 컬 | C11: 이두 | D11: 30 | E11: 4 | F11: 8~12 | G11: 40 | H11: 70 | I11: =IF(E11=0,0,ROUND((E11*(G11+H11)+O11)/60,1)) -> 8.3 | J11: 전완 | K11: 반동이 차단되는 종목. 인클라인(9일차)과 각도를 나눈다 [2026-09-07 마지막 세트 드롭 2단 — 실패 뒤 쉬지 않고 20~30% 내려 두 번. 팔꿈치가 패드에 고정돼 지쳐도 자세가 남는 종목이라 이두 드롭은 여기 한 곳. 세트 수 그대로, 증량 판정은 앞 세트로만. +60초는 O열] | L11: EZ바 프리처 컬 / 머신 프리처 컬 / 컨센트레이션 컬 | O11: 60
A12: 7 | B12: 트랩바 슈러그 | C12: 승모(상부) | D12: 15 | E12: 4 | F12: 10~12 | G12: 40 | H12: 90 | I12: =IF(E12=0,0,ROUND((E12*(G12+H12)+O12)/60,1)) -> 8.7 | J12: 전완 · 기립근 | K12: 몸 옆에서 잡는 중립 그립이라 견갑골이 전인되지 않는다 — 바벨(몸 앞)보다 승모 상부 섬유 방향에 맞고 가동범위도 더 나온다. 어깨를 위로만, 돌리지 말 것 (회전은 가동범위를 늘리는 게 아니라 견봉하 공간만 좁힌다). 맨 위에서 1초 정지 — 정지 없이 하면 반동으로 끝난다. 턱은 당기고 목은 중립 (목을 앞으로 빼면 경추 신전근이 일한다). 그립이 승모보다 먼저 나가므로 스트랩 권장 — 전완은 이미 주 7세트 직접으로 충족돼 여기서 그립을 훈련할 이유가 없다. #8 자리인 이유: 앞의 로우 7세트 + 스캡 슈러그로 그립이 지쳐 있어 프리쳐 컬·리스트 컬보다 뒤에 와야 연쇄 피해가 없다. 7일차 오버헤드 슈러그(승모 하부·상방회전)와는 다른 근육이므로 대체가 아니라 추가다. | L12: 덤벨 슈러그 (트랩바 없을 때 — 몸 옆 그립 동일) / 스미스 슈러그 (궤도 고정) / 바벨 슈러그 (몸 앞이라 가동범위 약간 손해) / 케이블 슈러그
A13: 8 | B13: 시티드 카프 레이즈 | C13: 종아리 | D13: 8 | E13: 2 | F13: 12~15 | G13: 40 | H13: 75 | I13: =IF(E13=0,0,ROUND((E13*(G13+H13)+O13)/60,1)) -> 3.8 | K13: [2026-09-05 4일차 → 6일차 이동] 오버헤드 슈러그에 자리를 내주고 왔다. 종아리 1·4·6·8일차(3/2/2/3일) — 4일차 스탠딩(비복근)과 6·8일차 시티드(가자미근)는 다른 근육이라 이틀 간격이 겹치지 않는다. [2026-09-05 9일차 → 4일차 이동] 종아리 1·4·6·8일차. [2026-09-04 신설] 무릎 굽힌 상태 — 가자미근. 1일차 스탠딩(비복근)과 각도를 나눈다. 8일차에 같은 종목이 4세트 있고 여기 2세트를 더해 종아리를 주당 10으로 올린다. | L13: 레그 프레스 카프 / 스탠딩 카프 (기계가 찼을 때)
A14: 9 | B14: 케이블 힙 외전 | C14: 중둔근 | D14: 10 | E14: 3 | F14: 12~15 (좌우) | G14: 80 | H14: 75 | I14: =IF(E14=0,0,ROUND((E14*(G14+H14)+O14)/60,1)) -> 7.8 | K14: [2026-09-05 9일차 → 6일차 이동] 중둔근을 3·6·9일차 3일/3일/4일 간격으로 펴려고 — 스쿼트·데드 다음 날 어느 쪽에도 엉덩이 고립을 두지 않는 자리는 여기뿐이다. 서서 하는 케이블이라 척추 부하 0, 데드 이틀 전. 백 익스텐션(옆 체육관) 앞 마지막 본관 종목. 관상면 외전 — 고관절 날로 복귀 (v18). 5일 버전 8일차 과부하 때문에 3일차로 갔던 종목이나 그 사유 소멸. 앉는 시간이 길면 대둔근보다 중둔근이 먼저 잠든다. (이 자리의 트렁크 로테이션은 v17 제외 — 복부 직접 8 유지) | L14: 밴드 몬스터 워크 / 사이드 라잉 힙 외전 / 힙 어브덕션 머신
A15: 10 | B15: 백 익스텐션 (45도) | C15: 기립근 | D15: 맨몸 | E15: 3 | F15: 12~15 | G15: 40 | H15: 60 | I15: =IF(E15=0,0,ROUND((E15*(G15+H15)+O15)/60,1)) -> 5 | K15: [2026-09-04 순서 변경] 기구가 옆 체육관에 있어 세션 맨 마지막으로 내렸다 — 본 체육관 일을 전부 끝내고 이동한다. 앞으로 종목을 추가할 때 이 뒤에 붙이지 말 것. 45도 백 익스텐션, 이 프로그램의 원래 설계 종목이었는데 기구를 못 써서 덤벨 RDL로 대체해 뒀던 것을 되돌렸다. **척추 신전을 강조해서 한다** — 등을 편 채 고관절만 접는 힌지식으로 하면 둔근·햄스트링이 주동근이 되고 기립근은 버티기만 한다. 옆 체육관까지 갔는데 그러면 헛걸음이다. | L15: 원판 5~10kg 안고 (맨몸이 쉬워지면) / 굿모닝(스미스) / 덤벨 루마니안 데드리프트
D16: 세트 합계 | E16: =SUM(E6:E15) -> 28 | I16: =ROUND(SUM(I6:I15),0) -> 70
A17: 이동 (2026-09-05)
A18: · 스탠딩 카프 → 4일차, 중량 크런치 → 7일차, 9일차 케이블 힙 외전이 8번(백 익스텐션 앞)으로 왔다. 중둔근 3·6·9일차 — 스쿼트·데드 다음 날에는 엉덩이 고립이 없다. 31세트 · 약 72분, 가장 길던 날(77분)이 내려왔다.
A19: · 오버헤드 슈러그 → 4일차, 4일차 시티드 카프 2세트가 8번(힙 외전 앞)으로 왔다. 6·7일차 이틀 연속이던 승모 하부가 풀렸다. 30세트 · 약 71분.
A20: · 시티드 케이블 로우 5 → 양팔 3 + 원암 2 (사용자 요청). 3번 원암 케이블 로우를 새로 두고 스캡 슈러그부터 번호가 하나씩 밀렸다. 광배 직접 세트는 5 그대로 · 30세트 · 약 72분.
A22: 드롭 세트 (2026-09-07)
A23: · 원암 로우(+120초 · 편측) · 프리쳐 컬(+60초) 마지막 세트에 드롭 2단 (사용자 요청). 원암 로우는 몸통이 돌아가거나 팔로 당기기 시작하면 그 자리에서 끝 — 지친 상태에서 광배가 빠지기 가장 쉬운 종목이다. 이두 드롭은 여기 한 곳이다. 9일차 인클라인 컬은 이틀 뒤 1일차 친업 때문에 직선으로 둔다.
A24: · O열 '드롭(초)'는 마지막 세트에 더해지는 시간이다. I열 종목 분에 합산되고, 앱 타이머는 마지막 세트를 그만큼 늘린 뒤 '드롭세트'라고 읊는다. E열 세트 수와 세트검산은 건드리지 않는다.
A25: · 스캡 슈러그 마지막 세트에도 드롭 2단, +60초 (사용자 요청, 2026-09-07 추가). 핀 스택 단관절이고 그날 승모 중부 마지막 종목이다. 지치면 팔로 당겨 로우가 되는데 그래도 등 상부라 손해가 작다. 6일차 드롭은 셋, 약 76분.

Sheet D7_밀기B
A1: 7일차 — 밀기 B (수직)
A2: 오버헤드 프레싱 · 흉근 상부 · 어깨 측면/후면. 벤치(2일차)와 5일 간격이라 무게가 온전히 나온다. [2026-09-05] 4일차 디클라인 케이블 플라이 3세트가 왔다 — 흉근 9세트(헤머 · 인클라인 머신 · 디클라인). 6일차 중량 크런치 3세트도 마지막에 왔다 — 약 72분. 디클라인 플라이 마지막 세트 드롭 +1분 — 약 73분 (2026-09-07).
A4: 메인: 밀리터리 프레스
A5: 중량(Kg) | B5: 반복 | C5: 세트
A6: =MAX(20,(MROUND(시작중량_설정!$E$10*0.4,1)+(MOD(MROUND(시작중량_설정!$E$10*0.4,1),5)=4))) -> 20 | B6: 5 | C6: 2
A7: =IF(MAX(20,(MROUND(시작중량_설정!$E$10*0.6,1)+(MOD(MROUND(시작중량_설정!$E$10*0.6,1),5)=4)))<=MAX(20,(MROUND(시작중량_설정!$E$10*0.4,1)+(MOD(MROUND(시작중량_설정!$E$10*0.4,1),5)=4))),"생략",MAX(20,(MROUND(시작중량_설정!$E$10*0.6,1)+(MOD(MROUND(시작중량_설정!$E$10*0.6,1),5)=4)))) -> 생략 | B7: 5 | C7: 1
A8: =IF(MAX(20,(MROUND(시작중량_설정!$E$10*0.75,1)+(MOD(MROUND(시작중량_설정!$E$10*0.75,1),5)=4)))<=MAX(20,(MROUND(시작중량_설정!$E$10*0.6,1)+(MOD(MROUND(시작중량_설정!$E$10*0.6,1),5)=4))),"생략",MAX(20,(MROUND(시작중량_설정!$E$10*0.75,1)+(MOD(MROUND(시작중량_설정!$E$10*0.75,1),5)=4)))) -> 생략 | B8: 3 | C8: 1
A9: =IF(MAX(20,(MROUND(시작중량_설정!$E$10*0.9,1)+(MOD(MROUND(시작중량_설정!$E$10*0.9,1),5)=4)))<=MAX(20,(MROUND(시작중량_설정!$E$10*0.75,1)+(MOD(MROUND(시작중량_설정!$E$10*0.75,1),5)=4))),"생략",MAX(20,(MROUND(시작중량_설정!$E$10*0.9,1)+(MOD(MROUND(시작중량_설정!$E$10*0.9,1),5)=4)))) -> 23 | B9: 2 | C9: 1
A10: =시작중량_설정!$E$10 -> 26 | B10: 5 | C10: 3
A11: ↑ '시작중량_설정'과 자동 연동. 20 = 빈 봉. '생략'은 앞 세트와 중량이 겹쳐 불필요하다는 뜻.
A13: 웜업 — 회전근개 (세트 카운트 제외)
A14: · 케이블 외회전 2세트 × 12~15회. 팔꿈치 90도로 접어 옆구리에 붙이고 바깥으로만 회전.
A15: · 매우 가볍게 — 2.5~5kg. 무거우면 광배와 후면 삼각근이 대신 일하며 목적을 잃는다.
A16: · 근비대 항목이 아니라 관절 준비 항목이므로 세트 합계에 넣지 않는다.
A18: 운동 구성
A19: # | B19: 종목 | C19: 근육군 | D19: 중량(Kg) | E19: 세트 | F19: 횟수 | G19: 수행(초) | H19: 휴식(초) | I19: 종목 분 | J19: 간접 자극 | K19: 메모 | L19: 대체 종목 | M19: 세트별 휴식(초) | N19: 슈퍼세트 | O19: 드롭(초)
A20: 1 | B20: 밀리터리 프레스 (본세트) | C20: 삼각근(전면) | D20: =시작중량_설정!$E$10 -> 26 | E20: 3 | F20: 5 | G20: 30 | H20: 180 | I20: =IF(E20=0,0,ROUND((E20*(G20+H20)+O20)/60,1)) -> 10.5 | J20: 삼두 · 삼각근(측면) | K20: 벤치와 5일 간격 — 5일 버전의 "전날 벤치 여파" 문제가 사라진 자리. 팔꿈치 다 내리지 말 것 | L20: 스미스 오버헤드 프레스 / 숄더 프레스 머신 / 덤벨 숄더 프레스 (가동범위 ↑) / 아놀드 프레스 | M20: 165/180/195
A21: 2 | B21: 머신 숄더 프레스 | C21: 삼각근(전면) | D21: 25 | E21: 3 | F21: 12 | G21: 40 | H21: 120 | I21: =IF(E21=0,0,ROUND((E21*(G21+H21)+O21)/60,1)) -> 8 | J21: 승모 · 삼각근(측면) | K21: 주동은 전면이나 오버헤드라 측면도 상당히 쓴다. 그립 넓게 — 좁으면 승모가 대신 일한다 | L21: 덤벨 숄더 프레스 / 스미스 오버헤드 프레스 / 아놀드 프레스
A22: 3 | B22: 오버헤드 슈러그(스미스) | C22: 승모(하부) | D22: 20 | E22: 3 | F22: 12~15 | G22: 40 | H22: 60 | I22: =IF(E22=0,0,ROUND((E22*(G22+H22)+O22)/60,1)) -> 5 | J22: 전거근 | K22: 머신 숄더 프레스 직후 — 오버헤드 각도가 이미 나와 있어 세팅 이동이 없다. 팔꿈치 편 채 견갑골만 2~3cm 위로. 팔꿈치가 굽으면 그건 프레스지 슈러그가 아니다 | L22: 스미스 오버헤드 슈러그 (1순위 — 궤도 고정으로 안정화 부담 없음) / 숄더 프레스 머신에서 팔 편 채 밀어올리기 / 덤벨 오버헤드 슈러그 (좌우 독립이나 안정화가 먼저 한계에 닿는다) / 케틀벨 보텀업 홀드
A23: 4 | B23: 헤머스트랭스 체스트 프레스 | C23: 흉근(중하부) | D23: 25 | E23: 3 | F23: 8~12 | G23: 40 | H23: 150 | I23: =IF(E23=0,0,ROUND((E23*(G23+H23)+O23)/60,1)) -> 9.5 | J23: 삼두 | K23: 좌우 독립 + 궤도 고정. 벤치(2일차)가 수평 메인이므로 여기선 보조 볼륨 [v17 제외 — 흉근 합산 천장(19→16) 감량, 벤치·딥스·인클라인이 담당] | L23: 케이블 체스트 프레스 (전 구간 장력) / 덤벨 프레스 (가동범위 ↑) / 스미스 벤치는 대체 불가
A24: 5 | B24: 인클라인 벤치프레스 머신 | C24: 흉근(상부) | D24: 35 | E24: 3 | F24: 8~10 | G24: 40 | H24: 150 | I24: =IF(E24=0,0,ROUND((E24*(G24+H24)+O24)/60,1)) -> 9.5 | J24: 삼두·전면삼각 | K24: 쇄골지. 오버헤드 프레싱과 각도가 이어져 세팅 이동이 적다 [2026-09-04 4→6] 흉근 상부 보강. 2일차 인클라인 플라이와 짝. | L24: 인클라인 스미스 프레스 / 인클라인 덤벨 프레스 (가동범위 ↑) / 인클라인 체스트 프레스 머신
A25: 6 | B25: 디클라인 케이블 플라이 | C25: 흉근(중하부) | D25: 10 | E25: 3 | F25: 8~12 | G25: 40 | H25: 90 | I25: =IF(E25=0,0,ROUND((E25*(G25+H25)+O25)/60,1)) -> 7.5 | K25: [2026-09-05 4일차 → 7일차 이동 — 사용자 요청] 흉근 중하부 고립. 헤머 체스트·인클라인 머신 두 프레스 뒤 마무리 자리다. 위에서 아래로 내리는 궤적이라 하부 섬유 비중이 크고, 케이블이라 수축 지점에서도 장력이 유지된다. 흉근 합산이 천장(20)을 넘어 있어 세트 질이 떨어지면 먼저 빼는 후보가 이 3세트다. [이력] 이 행은 v18 전 삼두 종목 자리였고, 2026-09-04 2일차 → 4일차, 오늘 7일차로 왔다. [2026-09-07 마지막 세트 드롭 2단 — 실패 뒤 쉬지 않고 핀 20~30% 내려 두 번. 팔을 굽혀 프레스처럼 밀기 시작하면 끝. 4일차 펙덱과 3일 간격. 세트 수 그대로, 증량 판정은 앞 세트로만. +60초는 O열] | L25: 케이블 크로스오버 (위→아래) / 디클라인 덤벨 플라이 / 펙덱 플라이 (시트를 높여 하부 각) | O25: 60
A26: 7 | B26: 벤트오버 레터럴 레이즈 머신 | C26: 삼각근(후면) | D26: 15 | E26: 3 | F26: 12~15 | G26: 40 | H26: 70 | I26: =IF(E26=0,0,ROUND((E26*(G26+H26)+O26)/60,1)) -> 5.5 | K26: 수평 외전. 2일차 리버스 펙덱 · 9일차 후면 3종목(9세트)과 함께 후면 사이클당 3회 16세트를 만든다 | L26: 리버스 펙덱 / 케이블 리버스 플라이 / 인클라인 벤치에 엎드려 덤벨 리어델트
A27: 8 | B27: 원암 사이드 케이블 레터럴 레이즈 | C27: 삼각근(측면) | D27: 5 | E27: 3 | F27: 10~12 | G27: 70 | H27: 70 | I27: =IF(E27=0,0,ROUND((E27*(G27+H27)+O27)/60,1)) -> 7 | K27: 몸을 반대로 기울여 늘어난 위치부터 부하. 덤벨 레터럴(2일차)이 못 거는 구간 | L27: 케이블 원암 레터럴 레이즈 (최우선) / 원암 레터럴 레이즈 머신
A28: 9 | B28: 프론 Y 레이즈 | C28: 승모(하부) | D28: 2~5 | E28: 3 | F28: 12~15 | G28: 40 | H28: 60 | I28: =IF(E28=0,0,ROUND((E28*(G28+H28)+O28)/60,1)) -> 5 | J28: 후면 삼각근 | K28: 벤트오버 레터럴과 같은 인클라인 벤치 — 세팅 그대로 이어서. 매우 가볍게. 오버헤드 슈러그가 상방회전, 이쪽은 하강 — 역할이 다르다 [2026-09-04 0→3] 꺼져 있던 종목을 켰다. 승모 하부가 실질 4.5로 가장 모자란데 이 종목이 0세트로 잠들어 있었다 — 새 종목을 찾기 전에 이것부터. | L28: 케이블 Y 레이즈 / 페이스풀 (마지막에 견갑골 하강) / 프론 스윔
A29: 10 | B29: 중량 크런치 | C29: 복부 | D29: 15 | E29: 3 | F29: 12 | G29: 40 | H29: 60 | I29: =IF(E29=0,0,ROUND((E29*(G29+H29)+O29)/60,1)) -> 5 | K29: [2026-09-05 6일차 → 7일차 이동] 6일차 길이를 내리고 복부를 1·3·7일차로 펴려고. 데드 전날이라 부하 건 굴곡이 이상적이진 않다 — 마지막 종목으로 가볍게, 데드 셋업에서 배에 힘이 덜 들어가면 6일차로 되돌린다. 복부 굴곡(상부). 1일차 레그레이즈(하부)와 굴곡 축을 나눈다. [2026-09-04 6→3] 한 종목을 한 세션에서 6세트 연달아 하면 뒤쪽 세트의 자극당 값이 떨어진다 — 9일차 후면삼각 9세트를 3종목으로 쪼갠 것과 같은 이유다. 뺀 3세트는 1일차 케이블 트렁크 로테이션으로 갔고 복부 총량(13 · 주당 10.1)은 그대로다. | L29: 케이블 크런치 (점진적 과부하에 최적 — 1순위) / 압도미널 크런치 머신 / 인클라인 싯업
D30: 세트 합계 | E30: =SUM(E20:E29) -> 30 | I30: =ROUND(SUM(I20:I29),0) -> 73
A31: 하부 승모 — 세 패턴 (v3)
A32: · 하부 승모의 일은 두 갈래다: 견갑골 하강, 그리고 팔이 올라갈 때의 상방회전.
A33: · 스캡 풀업(월 웜업) = 순수 하강 · 프론 Y(7일차) = 하강 + 후인 · 오버헤드 슈러그(7일차) = 상방회전.
A34: · 상방회전은 팔이 머리 위로 간 각도에서만 훈련된다 — 지금까지 프로그램에 통째로 비어 있던 패턴.
A35: · 전거근이 함께 온다. 전거근이 약하면 하부 승모를 키워도 견갑골이 제 위치로 안 간다.
A36: · 가동범위가 아주 작다. 견갑골만 2~3cm 올렸다 내리는 동작이고, 그 이상은 팔꿈치가 굽은 것이다.
A37: · 무게는 오버헤드로 안정적으로 지지할 수 있는 것보다 가볍게. 스미스나 머신 권장.
A38: · 하부 승모는 무게로 밀어붙일 수 없다. 과부하는 정지 2~3초 · 하강 3초 · 반복 수 확장으로.
A40: 이동 (2026-09-05)
A41: · 4일차 디클라인 케이블 플라이 3세트가 인클라인 머신 뒤 6번으로 왔다 — 사용자 요청. 흉근 9세트(헤머 3 · 인클라인 머신 3 · 디클라인 3). 27세트 · 약 67분.
A42: · 6일차 중량 크런치 3세트가 마지막(10번)으로 왔다. 복부 1·3·7일차. 데드 전날이라 가볍게 — 셋업에서 배 힘이 덜 들어가면 6일차로 되돌린다. 30세트 · 약 72분.
A44: 드롭 세트 (2026-09-07)
... A46: · O열 '드롭(초)'는 마지막 세트에 더해지는 시간이다. I열 종목 분에 합산되고, 앱 타이머는 마지막 세트를 그만큼 늘린 뒤 '드롭세트'라고 읊는다. E열 세트 수와 세트검산은 건드리지 않는다.

Sheet D8_하체B
A1: 8일차 — 하체 B (고관절 지배)
A2: · 힙 힌지 · 둔근. 3일차 하체 A(무릎 지배)와 5일 간격. 다음 날은 9일차 어깨 — 척추 부하가 0인 고립 세션이라 사실상 회복일이다.
A4: 메인: 데드리프트
A5: 중량(Kg) | B5: 반복 | C5: 세트
A6: =MAX(20,(MROUND(시작중량_설정!$E$8*0.4,1)+(MOD(MROUND(시작중량_설정!$E$8*0.4,1),5)=4))) -> 27 | B6: 5 | C6: 2
A7: =IF(MAX(20,(MROUND(시작중량_설정!$E$8*0.6,1)+(MOD(MROUND(시작중량_설정!$E$8*0.6,1),5)=4)))<=MAX(20,(MROUND(시작중량_설정!$E$8*0.4,1)+(MOD(MROUND(시작중량_설정!$E$8*0.4,1),5)=4))),"생략",MAX(20,(MROUND(시작중량_설정!$E$8*0.6,1)+(MOD(MROUND(시작중량_설정!$E$8*0.6,1),5)=4)))) -> 40 | B7: 5 | C7: 1
A8: =IF(MAX(20,(MROUND(시작중량_설정!$E$8*0.75,1)+(MOD(MROUND(시작중량_설정!$E$8*0.75,1),5)=4)))<=MAX(20,(MROUND(시작중량_설정!$E$8*0.6,1)+(MOD(MROUND(시작중량_설정!$E$8*0.6,1),5)=4))),"생략",MAX(20,(MROUND(시작중량_설정!$E$8*0.75,1)+(MOD(MROUND(시작중량_설정!$E$8*0.75,1),5)=4)))) -> 50 | B8: 3 | C8: 1
A9: =IF(MAX(20,(MROUND(시작중량_설정!$E$8*0.9,1)+(MOD(MROUND(시작중량_설정!$E$8*0.9,1),5)=4)))<=MAX(20,(MROUND(시작중량_설정!$E$8*0.75,1)+(MOD(MROUND(시작중량_설정!$E$8*0.75,1),5)=4))),"생략",MAX(20,(MROUND(시작중량_설정!$E$8*0.9,1)+(MOD(MROUND(시작중량_설정!$E$8*0.9,1),5)=4)))) -> 60 | B9: 2 | C9: 1
A10: =시작중량_설정!$E$8 -> 67 | B10: 5 | C10: 1
A11: ↑ '시작중량_설정'과 자동 연동. 20 = 빈 봉. '생략'은 앞 세트와 중량이 겹쳐 불필요하다는 뜻.
A13: 운동 구성
A14: # | B14: 종목 | C14: 근육군 | D14: 중량(Kg) | E14: 세트 | F14: 횟수 | G14: 수행(초) | H14: 휴식(초) | I14: 종목 분 | J14: 간접 자극 | K14: 메모 | L14: 대체 종목 | M14: 세트별 휴식(초) | N14: 슈퍼세트 | O14: 드롭(초)
A15: 1 | B15: 데드리프트 (본세트) | C15: 기립근 | D15: =시작중량_설정!$E$8 -> 67 | E15: 1 | F15: 5 | G15: 35 | H15: 240 | I15: =IF(E15=0,0,ROUND((E15*(G15+H15)+O15)/60,1)) -> 4.6 | J15: 광배·햄스트링·둔근 | K15: 사이클당 1회. 다음 날이 9일차 어깨(레터럴·리버스 플라이뿐이라 척추 부하 0)라 이 자리가 가장 안전하다. 기립근 보조는 1일차 덤벨 RDL이 맡는다. [2026-09-04 — 톱 1세트 + 백오프 2세트로 확장. 이 종목은 사이클당 5회 수행으로 +5kg를 올려 왔고, 노출 1회당 증량이 스쿼트(25회에 +5kg)의 5배였다. 5년 공백에서 폼을 다시 배우는 종목을 가장 적은 반복으로 밀고 있었다는 뜻이다. 톱세트 강도는 그대로 두고 반복 노출만 3배로 늘린다] | L15: 트랩바 데드리프트 (요추 전단력 ↓) / 랙풀 (무릎 위에서 시작) / 스모 데드리프트
A16: 2 | B16: 데드리프트 (백오프) | C16: 기립근 | D16: =시작중량_설정!$E$8-증량기록!$C$5 -> 62 | E16: 2 | F16: 5 | G16: 35 | H16: 180 | I16: =IF(E16=0,0,ROUND((E16*(G16+H16)+O16)/60,1)) -> 7.2 | J16: 광배·햄스트링·둔근 | K16: 백오프 = 톱세트 − 5kg = 직전 사이클의 톱세트 중량. 즉 모든 중량을 두 번 만난다 — 한 사이클은 톱으로 5회, 다음 사이클은 백오프로 10회. 중량 하나당 노출이 5 → 15회다. 여기는 기록이 아니라 폼 연습 자리다. 여유 있게 5회, 매 렙 셋업을 새로 잡을 것 — 무겁게 느껴지면 톱세트가 과했던 것이다. [2026-09-13 정정] 현장 복귀판에도 같은 구조를 넣었다 — 복귀_일_등에 톱 1 + 백오프 2. 복귀에서 상한인 것은 톱세트뿐이고, 백오프는 직전 사이클 중량이라 톱엔드 노출을 안 늘린다. | L16: 트랩바 데드리프트 (요추 전단력 ↓) / 랙풀 (무릎 위에서 시작) / 스모 데드리프트
A17: 3 | B17: 힙 쓰러스트 | C17: 둔근 | D17: 25 | E17: 4 | F17: 8~12 | G17: 45 | H17: 150 | I17: =IF(E17=0,0,ROUND((E17*(G17+H17)+O17)/60,1)) -> 13 | J17: 햄스트링 | K17: 둔근 메인. 무겁게. 데드 뒤라 둔근이 예열된 상태 | L17: 힙 쓰러스트 머신 / 스미스 힙 쓰러스트 / 글룻 브릿지
A18: 4 | B18: 루마니안 데드리프트 | C18: 햄스트링 | D18: 35 | E18: 3 | F18: 8 | G18: 40 | H18: 150 | I18: =IF(E18=0,0,ROUND((E18*(G18+H18)+O18)/60,1)) -> 9.5 | J18: 둔근·기립근 | K18: 고관절 신전. 3일차 레그 컬(무릎 굴곡)과 기능이 다르다 | L18: 덤벨 RDL (좌우 독립) / 스티프 레그드 데드리프트 / 케이블 풀스루 (허리 부담 최소)
A19: 5 | B19: 원 레그 컬 | C19: 햄스트링 | D19: 15 | E19: 3 | F19: 10 | G19: 80 | H19: 120 | I19: =IF(E19=0,0,ROUND((E19*(G19+H19)+O19)/60,1)) -> 10 | K19: 레그 컬의 좌우 독립 버전. 약한 쪽이 강한 쪽에 묻히지 않는다 | L19: 싱글 레그 라잉 컬 / 싱글 레그 시티드 컬 / 케이블 레그 컬
A20: 6 | B20: 레그 프레스 | C20: 대퇴사두 | D20: 120 | E20: 3 | F20: 8~12 | G20: 45 | H20: 150 | I20: =IF(E20=0,0,ROUND((E20*(G20+H20)+O20)/60,1)) -> 9.8 | J20: 둔근 | K20: 수/토 3+3 분할. 데드·힙 이후라 대퇴가 예열된 상태에서 궤도 고정으로 확실히 간다 [2026-09-07 레그 익스텐션과 자리 바꿈 — 복합을 먼저, 고립 드롭을 마지막에] | L20: 핵 스쿼트 / 레그 익스텐션 / 프론트 스쿼트 / 45도 레그 프레스
A21: 7 | B21: 레그 익스텐션 | C21: 대퇴사두 | D21: 42 | E21: 4 | F21: 10~12 | G21: 40 | H21: 120 | I21: =IF(E21=0,0,ROUND((E21*(G21+H21)+O21)/60,1)) -> 11.9 | K21: 대퇴사두 사이클당 2회를 만들기 위한 배치. 3일차 스쿼트 볼륨과 5일 간격 [2026-09-07 레그 프레스 뒤로 이동 + 마지막 세트 드롭 2단 — 실패 뒤 쉬지 않고 핀 20~30% 내려 두 번. 드롭으로 대퇴를 다 쓴 뒤 프레스를 하면 프레스 3세트가 죽어서 순서를 바꿨다. 세트 수 그대로, 증량 판정은 앞 세트로만. +75초는 O열] | L21: 싱글 레그 익스텐션 / 시시 스쿼트 / 레그 프레스 발판 높게 | O21: 75
A22: 8 | B22: 시티드 카프 레이즈 | C22: 종아리 | D22: 8 | E22: 4 | F22: 12~15 | G22: 40 | H22: 75 | I22: =IF(E22=0,0,ROUND((E22*(G22+H22)+O22)/60,1)) -> 7.7 | K22: 무릎 굽힘 — 가자미근 주도. 3일차 스탠딩(비복근)과 역할이 다르다 | L22: 시티드 카프 레이즈 머신 (1순위) / 레그 프레스에서 무릎 굽힌 채 / 덤벨을 무릎에 올리고
D23: 세트 합계 | E23: =SUM(E15:E22) -> 24 | I23: =ROUND(SUM(I15:I22),0) -> 74
A24: 드롭 세트 (2026-09-07)
A25: · 레그 프레스 ↔ 레그 익스텐션 자리 바꿈 — 복합을 먼저, 고립을 마지막에. 익스텐션 마지막 세트에 드롭 2단, +75초 (사용자 요청). 드롭으로 대퇴를 다 쓴 뒤 프레스를 하면 프레스 3세트가 죽어서 순서를 바꿨다. 다음 하체는 3일차, 5일 뒤라 회복이 겹치지 않는다.
A26: · O열 '드롭(초)'는 마지막 세트에 더해지는 시간이다. I열 종목 분에 합산되고, 앱 타이머는 마지막 세트를 그만큼 늘린 뒤 '드롭세트'라고 읊는다. E열 세트 수와 세트검산은 건드리지 않는다.

Sheet D9_어깨팔B
A1: 9일차 — 어깨·팔 B
A2: 측면 · 후면 · 전면 삼각근 + 하부 승모 + 흉근 상부 플라이 + 삼두 · 이두 · 전완 + 내전근·중둔근. 약 70분. 옛 8일차 어깨 세션의 절반 — 나머지 절반은 4일차 어깨·팔 A. 8일차 데드 다음 날이라 척추 부하 0은 그대로다. [2026-09-05] 인클라인 덤벨 플라이 3세트 추가(5번). 이너·아우터 타이·리스트 컬(손등 위)이 4일차에서 왔고 리버스 리스트 컬·리버스컬·시티드 카프는 4일차로, 케이블 힙 외전은 6일차로 갔다.
A3: 웜업 — 케이블 외회전 2세트 × 12~15 (세트 카운트 제외): 매우 가볍게 2.5~5kg. 팔꿈치를 90도로 접어 옆구리에 붙이고 바깥으로만 회전. 대체: 밴드 외회전 / 아주 가벼운 페이스풀.
A4: 운동 구성
A5: # | B5: 종목 | C5: 근육군 | D5: 중량(Kg) | E5: 세트 | F5: 횟수 | G5: 수행(초) | H5: 휴식(초) | I5: 종목 분 | J5: 간접 자극 | K5: 메모 | L5: 대체 종목 | M5: 세트별 휴식(초) | N5: 슈퍼세트 | O5: 드롭(초)
A6: 1 | B6: 리닝 원암 케이블 레터럴 레이즈 | C6: 삼각근(측면) | D6: 5 | E6: 3 | F6: 12~15 | G6: 80 | H6: 70 | I6: =IF(E6=0,0,ROUND((E6*(G6+H6)+O6)/60,1)) -> 7.5 | K6: 기둥을 잡고 몸을 반대로 기울여 늘어난 위치부터 부하가 걸린다 — 머신·덤벨이 못 거는 구간이다. 좌우 각 2세트. 7일차에도 같은 종목이 있지만 5일 간격이라 겹치지 않는다. | L6: 케이블 비하인드백 레터럴 / 로우 풀리 원암 레터럴 / 인클라인 벤치에 옆으로 누워 덤벨 레터럴
A7: 2 | B7: 인클라인 벤치 프론 리어 델트 레이즈 | C7: 삼각근(후면) | D7: 5 | E7: 3 | F7: 12~15 | G7: 40 | H7: 70 | I7: =IF(E7=0,0,ROUND((E7*(G7+H7)+O7)/60,1)) -> 5.5 | K7: 가슴을 벤치에 대고 엎드려 상체를 고정한다 — 반동과 기립근 개입이 통째로 차단돼 후면만 남는다. 자유중량이라 궤도가 고정된 4번과 다른 안정화 요구가 붙는다. 아주 가볍게, 무게보다 정지 1초. | L7: 프론 덤벨 리어 레이즈 (평벤치) / 시티드 벤트오버 덤벨 리어 레이즈 / 리버스 펙덱
A8: 3 | B8: 머신 숄더 프레스 | C8: 삼각근(전면) | D8: 25 | E8: 3 | F8: 12 | G8: 40 | H8: 120 | I8: =IF(E8=0,0,ROUND((E8*(G8+H8)+O8)/60,1)) -> 8 | J8: 삼두 · 삼각근(측면) | K8: [2026-09-04 신설] 전면삼각 직접이 6세트(7일차 밀리터리 3 + 머신 숄더 3)뿐이라 측면 18 · 후면 17에 견주면 얇았다. 9일 주기 전환으로 주당 9.7까지 내려와 이 자리를 만들었다. 레터럴·리어 6종목 뒤에 두는 이유: 앞에 두면 프레스 피로로 레이즈 중량이 눌린다. 여기 목적은 근력이 아니라 볼륨이므로 중량이 7일차보다 낮아도 된다. | L8: 덤벨 숄더 프레스 / 스미스 오버헤드 프레스
A9: 4 | B9: 프론 Y 레이즈 | C9: 승모(하부) | D9: 2~5 | E9: 3 | F9: 12~15 | G9: 40 | H9: 60 | I9: =IF(E9=0,0,ROUND((E9*(G9+H9)+O9)/60,1)) -> 5 | J9: 삼각근(후면) | K9: [2026-09-04 신설] 승모 하부 세 번째 자리. 7일차에서 0세트로 꺼져 있던 종목을 그쪽에서 켜고 여기에도 뒀다. 견갑 하강 + 상방회전. 엎드려 팔을 Y자로 — 중량보다 견갑이 먼저 움직이는지가 중요하다. | L9: 인클라인 벤치 프론 Y / 케이블 로 투 하이 (한 팔)
A10: 5 | B10: 인클라인 덤벨 플라이 | C10: 흉근(상부) | D10: 8 | E10: 3 | F10: 10~12 | G10: 40 | H10: 105 | I10: =IF(E10=0,0,ROUND((E10*(G10+H10)+O10)/60,1)) -> 7.3 | K10: [2026-09-05 신설 — 사용자 요청] 2일차 인클라인 플라이의 두 번째 자리. 같은 날 4일차 인클라인 스미스 4→3 · 7일차 인클라인 머신 6→3으로 프레스를 줄이고 플라이를 더한 것이라, 흉근 상부는 프레스 6 + 플라이 7 = 직접 13(2·4·7·9일차, 주당 9.1)이 된다. 프론 Y와 같은 인클라인 벤치에서 등을 대고 이어서 한다 — 세팅 이동 없음. 늘어난 구간에서 멈추지 말고 부드럽게 (2일차 메모와 같다). 데드 다음 날이지만 척추 부하 0이라 이 날의 성격은 그대로다. 흉근 합산은 천장(20)을 여전히 넘으므로(주당 21.7) 세트 질이 떨어지면 먼저 빼는 후보는 4일차 디클라인 케이블 플라이 3세트다. | L10: 케이블 크로스오버 (아래→위) / 펙덱 플라이 (등받이를 눕혀 인클라인 각으로) / 인클라인 머신 플라이
A11: 6 | B11: 라잉 트라이셉스 익스텐션 | C11: 삼두 | D11: 15 | E11: 4 | F11: 8~12 | G11: 40 | H11: 75 | I11: =IF(E11=0,0,ROUND((E11*(G11+H11)+O11)/60,1)) -> 7.7 | K11: 늘어난 구간 삼두 — 2일차에서 이동 (v18). 푸쉬다운 제외로 2일차 고정 사유가 소멸, 유일한 삼두 고립을 프레싱 전부 마친 뒤 마지막에. 팔꿈치 시큰하면 EZ바나 오버헤드 케이블로. (이 자리의 케이블 푸쉬다운은 v17 제외 — 삼두 간접 9로 충족) | L11: 오버헤드 케이블 익스텐션 / 스컬크러셔 / EZ바 라잉 익스텐션
A12: 7 | B12: 인클라인 덤벨 컬 | C12: 이두 | D12: 6 | E12: 4 | F12: 8~12 | G12: 40 | H12: 70 | I12: =IF(E12=0,0,ROUND((E12*(G12+H12)+O12)/60,1)) -> 7.3 | J12: 전완 | K12: 1일차에서 옮겨 왔다 (2026-08-28). 그 날은 친업 4 + 랫풀다운 3으로 이두가 간접 3.5세트분 지친 뒤였는데, 이 날은 어깨만 치므로 이두가 완전히 신선하다. 같은 3세트라도 자극당 값이 다르다. 인클라인 벤치에 기대 팔을 뒤로 늘어뜨린다 — 이두 장두가 늘어난 위치에서 시작하는 것이 이 종목의 전부다. 6일차 프리쳐 컬(짧아진 구간)과 각도를 나눈다. 어깨를 앞으로 말면 늘어난 구간이 사라진다. | L12: 케이블 컬 (뒤로 물러서서 스트레치 확보) / 스파이더 컬 (반대 각도) / 드래그 컬
A13: 8 | B13: 시티드 리스트 컬(손등 위) | C13: 전완 | D13: 10 | E13: 3 | F13: 15 | G13: 40 | H13: 60 | I13: =IF(E13=0,0,ROUND((E13*(G13+H13)+O13)/60,1)) -> 5 | K13: [2026-09-05 4일차 → 9일차 이동] 전완을 한 날에 몰지 않으려고 굴근·엎침(4일차 리버스 리스트 컬·리버스컬)과 날을 갈랐다 — 사용자 요청. 손목 신근. 타이핑으로 약해지는 쪽이라 비중을 더 준다 | L13: 케이블 리버스 리스트 컬 / 리버스 EZ바 컬 (상완요골근까지) / 덤벨로 한 손씩
A14: 9 | B14: 이너 타이 | C14: 내전근 | D14: 35 | E14: 5 | F14: 12~15 | G14: 40 | H14: 10 | I14: =IF(E14=0,0,ROUND((E14*(G14+H14)+O14)/60,1)) -> 4.2 | K14: [2026-09-05 4일차 → 9일차 이동] 3일차 바로 다음 날 같은 기구를 또 타는 게 부담스럽다는 요청. 내전근 3·9일차로 6일/4일 간격. 아우터 타이와 슈퍼세트(A)는 그대로. [2026-09-04 신설] 내전근을 성장 구간으로. 3일차에 4세트가 있지만 사이클당 1회라 모자랐다. 3일차와 같이 아우터 타이와 슈퍼세트로 묶는다 — 겸용 머신이라 패드만 뒤집으면 되어 전환이 10초고, 라운드 간 휴식은 아우터 쪽 105초가 맡는다. 길항근 쌍이라 서로의 피로를 나눠 갖지 않는다. | L14: 와이드 스탠스 레그 프레스 / 케이블 힙 내전 | N14: A
A15: 10 | B15: 아우터 타이 (힙 외전) | C15: 중둔근 | D15: 30~35 | E15: 5 | F15: 12~15 | G15: 40 | H15: 105 | I15: =IF(E15=0,0,ROUND((E15*(G15+H15)+O15)/60,1)) -> 12.1 | K15: [2026-09-05 4일차 → 9일차 이동] 케이블 힙 외전과 같은 날이라 중둔근 8세트(세션 상한선) — 앉아서(여기)·서서(힙 외전)로 각도가 다르다. 3일차와 6일/4일 간격. [2026-09-04 신설] 중둔근을 성장 구간으로. 3일차 4세트 · 8일차 케이블 힙 외전 3세트에 이어 세 번째 자리. 이너 타이와 슈퍼세트(A) — 이 105초가 두 종목의 라운드 간 휴식이다. | L15: 케이블 힙 외전 / 밴드 사이드 워크 | N15: A
D16: 세트 합계 | E16: =SUM(E6:E15) -> 36 | I16: =ROUND(SUM(I6:I15),0) -> 70
F17: 시티드 로우 3세트/ 그립 변경 3세트 추가
A18: 어깨·팔 B (2026-09-04 4-1-4-1 전환)
A19: · 옛 8일차 어깨 세션을 둘로 나눈 뒤쪽 절반이다. 측면 1 · 후면 1 · 전면 1 · 하부 승모 1에 삼두(옛 6일차에서) · 전완 2종(옛 5일차에서) · 이두 · 종아리. 측면 2 · 후면 2 · 이너/아우터는 4일차로 갔다.
A20: · 세트는 한 개도 안 늘었다. 40 → 30이 된 것은 10세트가 4일차로 간 것이지 뺀 게 아니다.
A21: · 시간 균등화로 8일차 케이블 힙 외전 3세트가 왔다. 4일차 아우터 타이와 짝 — 중둔근이 3·4·9일차. 케이블이라 척추 부하는 없다.
A22: · 아래 서술은 통합 시절(옛 8일차 · 40세트 · 6종목 분할) 기준이라 세트 수와 종목 번호가 지금과 다르다. 기록으로 남긴다.
A24: · 실패지점 1~2회 남기고 멈춘다. 9일차는 6일차부터 이어진 연속 구간 한가운데라 여기서 회복을 깎으면 다음 사이클 앞머리가 밀린다.
A25: · 세트 간 휴식 60~80초. 소근육 고립이라 길게 쉴 이유가 없다. 본세트 기준 약 39분 (웜업 별도).
A26: · 이 세션에 메인 리프트는 없다. 무게를 올리는 날이 아니라 볼륨을 채우는 날이다.
A27: · 척추 부하가 0이라 8일차 데드리프트 다음 날 자리로 안전하다 — 그게 이 날이 여기 있는 이유다. 이두 컬이 붙어도 그 성질은 그대로다.
A28: · 척추 부하가 0이라 8일차 데드리프트 다음 날 자리로 안전하다 — 그게 이 날이 여기 있는 이유다.
A29: 왜 프레스가 없는가
A30: · 볼륨 랜드마크 표에 전면 삼각근 행이 아예 없다 — 모든 프레스가 자동으로 채워주는 부위라 별도 하한을 잡지 않는다.
... A48: · 케이블 힙 외전은 6일차로 갔다 — 중둔근을 3·6·9일차로 펴고 이 날을 70분으로. 36세트.

Sheet 간접계수맵
A1: 간접 세트 계수 맵 — 세트검산 간접 열(C)의 계산 원천
A2: 각 줄 = "이 종목이 → 이 근육에 → 계수만큼 기여". 원천세트는 일차 시트 E열(설계 볼륨)에서 이름 매칭으로 자동 산출, 간접세트 = 계수 × 원천세트. 세트검산 C열이 이 표를 근육별 SUMIFS로 합산한다. E열 설계 세트 변경 시 자동 갱신. (세트검산 표시값은 0.5 단위 반올림)
A3: 이름 매칭 실패 줄 수 (0이어야 정상 — 0이 아니면 요일 시트에서 종목 이름이 바뀐 것이다) | F3: =COUNTIF($E$7:$E$80,"?") -> 0
A4: 계수 규칙(상한 0.5): 0.5 = 명확한 협력근(능동 수축·신전, 큰 ROM) · 0.33 = 부분 협력(관여하나 비주도, 또는 저반복 본세트의 협력근) · 0.2 = 미미한 동적 관여 · 0 = 순수 그립·안정화·고장력 등척성(길이변화 작음 — 자극 없음). 파란 계수 = 수정 가능 · 출처 G = 프로그램 선언(초록) / C = Claude 추가(주황)
A6: 원천 일차 | B6: 원천종목 | C6: 대상근육 | D6: 계수 | E6: 원천세트 | F6: 간접세트 | G6: 출처 | H6: 계수 근거
A7: D1_당기기A | B7: 친업 (어시스트 가능) | C7: 이두 | D7: 0.5 | E7: =IFERROR(INDEX(INDIRECT("'"&$A7&"'!$E$1:$E$45"),MATCH($B7,INDIRECT("'"&$A7&"'!$B$1:$B$45"),0)),"?") -> 4 | F7: =IF(ISNUMBER(E7),$D7*E7,0) -> 2 | G7: G | H7: 뒤침 그립 — 이두가 가장 유리한 자리에서 능동 굴곡하고 실패 근처까지 간다. 당기기 → 이두 계수는 그립으로 정한다: 뒤침 0.5 · 뉴트럴 0.33 · 엎침 0.2 (2026-09-04 정리).
A8: D1_당기기A | B8: 랫풀다운 | C8: 이두 | D8: 0.2 | E8: =IFERROR(INDEX(INDIRECT("'"&$A8&"'!$E$1:$E$45"),MATCH($B8,INDIRECT("'"&$A8&"'!$B$1:$B$45"),0)),"?") -> 3 | F8: =IF(ISNUMBER(E8),$D8*E8,0) -> 0.6 | G8: G | H8: 엎침 그립(친업과 반대로 잡는 자리) — 굽히는 일은 주로 상완근·상완요골근이 한다. 당기기 → 이두 계수는 그립으로 정한다: 뒤침 0.5 · 뉴트럴 0.33 · 엎침 0.2 (2026-09-04 정리). 만약 뉴트럴 손잡이로 바꾸면 0.33.
A9: D6_당기기B | B9: 해머 스트랭스 로우(오버그립) | C9: 이두 | D9: 0.2 | E9: =IFERROR(INDEX(INDIRECT("'"&$A9&"'!$E$1:$E$45"),MATCH($B9,INDIRECT("'"&$A9&"'!$B$1:$B$45"),0)),"?") -> 4 | F9: =IF(ISNUMBER(E9),$D9*E9,0) -> 0.8 | G9: G | H9: 엎침 그립 + 팔꿈치를 벌린 수평 로우 — 이두가 불리한 각도에 있고 실패는 등이 정한다. 당기기 → 이두 계수는 그립으로 정한다: 뒤침 0.5 · 뉴트럴 0.33 · 엎침 0.2 (2026-09-04 정리).
A10: D6_당기기B | B10: 시티드 케이블 로우 | C10: 이두 | D10: 0.33 | E10: =IFERROR(INDEX(INDIRECT("'"&$A10&"'!$E$1:$E$45"),MATCH($B10,INDIRECT("'"&$A10&"'!$B$1:$B$45"),0)),"?") -> 2 | F10: =IF(ISNUMBER(E10),$D10*E10,0) -> 0.66 | G10: G | H10: 좁은 뉴트럴 그립 — 이두와 상완근이 나눠 쓴다. 엎침(0.2)과 뒤침(0.5) 사이. 당기기 → 이두 계수는 그립으로 정한다: 뒤침 0.5 · 뉴트럴 0.33 · 엎침 0.2 (2026-09-04 정리).
A11: D2_밀기A | B11: 벤치프레스 (본세트) | C11: 삼두 | D11: 0.33 | E11: =IFERROR(INDEX(INDIRECT("'"&$A11&"'!$E$1:$E$45"),MATCH($B11,INDIRECT("'"&$A11&"'!$B$1:$B$45"),0)),"?") -> 5 | F11: =IF(ISNUMBER(E11),$D11*E11,0) -> 1.65 | G11: G | H11: 프레스 중 삼두 신전 — 5×5 저반복 본세트라 가슴이 먼저 실패하고 삼두 유효반복이 적다. 보조 프레스는 0.5 유지 (2026-09-04 0.5→0.33)
A12: D2_밀기A | B12: 딥스 | C12: 삼두 | D12: 0.5 | E12: =IFERROR(INDEX(INDIRECT("'"&$A12&"'!$E$1:$E$45"),MATCH($B12,INDIRECT("'"&$A12&"'!$B$1:$B$45"),0)),"?") -> 4 | F12: =IF(ISNUMBER(E12),$D12*E12,0) -> 2 | G12: G | H12: 딥스는 삼두 스트레치+신전 강함
A13: D7_밀기B | B13: 밀리터리 프레스 (본세트) | C13: 삼두 | D13: 0.33 | E13: =IFERROR(INDEX(INDIRECT("'"&$A13&"'!$E$1:$E$45"),MATCH($B13,INDIRECT("'"&$A13&"'!$B$1:$B$45"),0)),"?") -> 3 | F13: =IF(ISNUMBER(E13),$D13*E13,0) -> 0.99 | G13: G | H13: 오버헤드 프레스 삼두 신전 — 5×5 저반복 본세트 하향. 머신 숄더(0.5)와 구분 (2026-09-04 0.5→0.33)
A14: D7_밀기B | B14: 인클라인 벤치프레스 머신 | C14: 삼두 | D14: 0.5 | E14: =IFERROR(INDEX(INDIRECT("'"&$A14&"'!$E$1:$E$45"),MATCH($B14,INDIRECT("'"&$A14&"'!$B$1:$B$45"),0)),"?") -> 3 | F14: =IF(ISNUMBER(E14),$D14*E14,0) -> 1.5 | G14: G | H14: 프레스 중 삼두 신전
A15: D4_어깨팔A | B15: 인클라인 벤치프레스(스미스) | C15: 삼두 | D15: 0.5 | E15: =IFERROR(INDEX(INDIRECT("'"&$A15&"'!$E$1:$E$45"),MATCH($B15,INDIRECT("'"&$A15&"'!$B$1:$B$45"),0)),"?") -> 3 | F15: =IF(ISNUMBER(E15),$D15*E15,0) -> 1.5 | G15: C | H15: 프레스 중 삼두 신전 — 인클라인 벤치프레스 머신(0.5)과 같은 등급 (2026-09-04 신설)
A16: D9_어깨팔B | B16: 인클라인 덤벨 컬 | C16: 전완 | D16: 0.33 | E16: =IFERROR(INDEX(INDIRECT("'"&$A16&"'!$E$1:$E$45"),MATCH($B16,INDIRECT("'"&$A16&"'!$B$1:$B$45"),0)),"?") -> 4 | F16: =IF(ISNUMBER(E16),$D16*E16,0) -> 1.32 | G16: G | H16: 컬 중 상완요골근 동적 굴곡 — 부분 협력
A17: D6_당기기B | B17: 프리쳐 컬 | C17: 전완 | D17: 0.33 | E17: =IFERROR(INDEX(INDIRECT("'"&$A17&"'!$E$1:$E$45"),MATCH($B17,INDIRECT("'"&$A17&"'!$B$1:$B$45"),0)),"?") -> 4 | F17: =IF(ISNUMBER(E17),$D17*E17,0) -> 1.32 | G17: G | H17: 상완요골근 동적 굴곡
A18: D6_당기기B | B18: 트랩바 슈러그 | C18: 전완 | D18: 0 | E18: =IFERROR(INDEX(INDIRECT("'"&$A18&"'!$E$1:$E$45"),MATCH($B18,INDIRECT("'"&$A18&"'!$B$1:$B$45"),0)),"?") -> 4 | F18: =IF(ISNUMBER(E18),$D18*E18,0) -> 0 | G18: G | H18: 순수 그립 유지(스트랩 권장) — 성장 자극 없음
... A75: D6_당기기B | B75: 원암 케이블 로우 | C75: 승모(중부)·능형근 | D75: 0.5 | E75: =IFERROR(INDEX(INDIRECT("'"&$A75&"'!$E$1:$E$45"),MATCH($B75,INDIRECT("'"&$A75&"'!$B$1:$B$45"),0)),"?") -> 2 | F75: =IF(ISNUMBER(E75),$D75*E75,0) -> 1 | G75: G | H75: 견갑 후인 능동 수축 — 시티드 케이블 로우(0.5)와 같은 등급. 한 팔씩이라 몸통 회전이 섞이지만 후인은 그대로 일어난다 (2026-09-05 신설).

Sheet 세트검산
A1: 근육군별 주간 세트 — 검산 | G1: ■ 사이클 총량 예산 — 늘리려면 먼저 어딘가에서 빼라
A2: 세트는 근육군 단위로 센다. '하체 20세트'는 의미 없는 숫자 — 대퇴 18 / 햄스트링 2여도 하체 20이 된다. 집계는 일차 시트 E열(설계 세트) 기준이며 B~D열은 사이클당(주기 길이는 H2) 값이다. 판정(E열)은 J열의 주당 환산(사이클당 × 7/주기)으로 한다 — 볼륨 랜드마크가 주 단위이기 때문이다. 간접·실질은 0.5 단위 반올림으로 표시한다 — 메모의 계산 원값과 ±0.25 이내 차이가 날 수 있다. | G2: 주기(일) | H2: 10 | I2: 총량 상한 | J2: 244 | K2: 현재 총량 | L2: =B25 -> 240
A3: =IF($H$3<0,"⚠ 총량 상한 "&ABS($H$3)&"세트 초과 — 다른 종목에서 그만큼 빼기 전에는 추가 금지. 상한을 올리려면 아래 '상한 변경 이력'에 한 줄 남길 것.","") | G3: 잔여 예산 | H3: =$J$2-$L$2 -> 4 | I3: 실제 주당 | J3: =ROUND($L$2*7/$H$2,1) -> 168 | K3: 상태 | L3: =IF($H$3<0,"INVALID","VALID") -> VALID
A4: 근육군 | B4: 직접 세트 | C4: 간접 추정 | D4: 실질 | E4: 판정 | F4: 간접 출처 / 비고 | J4: ="주당 환산 (×7/"&$H$2&")" -> 주당 환산 (×7/10)
A5: 흉근(상부) | B5: =SUMIFS(D1_당기기A!$E:$E,D1_당기기A!$C:$C,$A5)+SUMIFS(D2_밀기A!$E:$E,D2_밀기A!$C:$C,$A5)+SUMIFS(D3_하체A!$E:$E,D3_하체A!$C:$C,$A5)+SUMIFS(D4_어깨팔A!$E:$E,D4_어깨팔A!$C:$C,$A5)+SUMIFS(D6_당기기B!$E:$E,D6_당기기B!$C:$C,$A5)+SUMIFS(D7_밀기B!$E:$E,D7_밀기B!$C:$C,$A5)+SUMIFS(D8_하체B!$E:$E,D8_하체B!$C:$C,$A5)+SUMIFS(D9_어깨팔B!$E:$E,D9_어깨팔B!$C:$C,$A5) -> 13 | C5: =MROUND(SUMIFS(간접계수맵!$F$7:$F$80,간접계수맵!$C$7:$C$80,$A5),0.5) -> 0 | D5: =B5+C5 -> 13 | E5: =IF(J5>20,"상한",IF(J5>=10,"성장",IF(J5>=8,"유지",IF(J5>=1,"유지 미만","미배치")))) -> 유지 | F5: 플랫 벤치의 쇄골지 관여(0.2)를 2026-09-04에 0으로 내렸다. 흉근 상/하는 H열에서 합산 판정하므로 서로에게 간접을 얹으면 합산이 이중 계상된다. | G5: 흉근 합산(상+중하) | H5: =SUM(D5:D6) -> 31 | I5: =IF(H5*7/$H$2>20,"주당 환산 천장(20) 초과 — 2·4·7·9일차 예외 허용 · 세트 질 관찰","") -> 주당 환산 천장(20) 초과 — 2·4·7·9일차 예외 허용 · 세트 질 관찰 | J5: =ROUND(D5*7/$H$2,1) -> 9.1 | L5: =ROUND(B5*7/$H$2,1) -> 9.1
A6: 흉근(중하부) | B6: =SUMIFS(D1_당기기A!$E:$E,D1_당기기A!$C:$C,$A6)+SUMIFS(D2_밀기A!$E:$E,D2_밀기A!$C:$C,$A6)+SUMIFS(D3_하체A!$E:$E,D3_하체A!$C:$C,$A6)+SUMIFS(D4_어깨팔A!$E:$E,D4_어깨팔A!$C:$C,$A6)+SUMIFS(D6_당기기B!$E:$E,D6_당기기B!$C:$C,$A6)+SUMIFS(D7_밀기B!$E:$E,D7_밀기B!$C:$C,$A6)+SUMIFS(D8_하체B!$E:$E,D8_하체B!$C:$C,$A6)+SUMIFS(D9_어깨팔B!$E:$E,D9_어깨팔B!$C:$C,$A6) -> 18 | C6: =MROUND(SUMIFS(간접계수맵!$F$7:$F$80,간접계수맵!$C$7:$C$80,$A6),0.5) -> 0 | D6: =B6+C6 -> 18 | E6: =IF(J6>20,"상한",IF(J6>=10,"성장",IF(J6>=8,"유지",IF(J6>=1,"유지 미만","미배치")))) -> 성장 | F6: 인클라인 머신의 중하부 관여(0.2)를 2026-09-04에 0으로 내렸다(흉근 상/하 교차 계상 제거). | J6: =ROUND(D6*7/$H$2,1) -> 12.6 | L6: =ROUND(B6*7/$H$2,1) -> 12.6
A7: 광배 | B7: =SUMIFS(D1_당기기A!$E:$E,D1_당기기A!$C:$C,$A7)+SUMIFS(D2_밀기A!$E:$E,D2_밀기A!$C:$C,$A7)+SUMIFS(D3_하체A!$E:$E,D3_하체A!$C:$C,$A7)+SUMIFS(D4_어깨팔A!$E:$E,D4_어깨팔A!$C:$C,$A7)+SUMIFS(D6_당기기B!$E:$E,D6_당기기B!$C:$C,$A7)+SUMIFS(D7_밀기B!$E:$E,D7_밀기B!$C:$C,$A7)+SUMIFS(D8_하체B!$E:$E,D8_하체B!$C:$C,$A7)+SUMIFS(D9_어깨팔B!$E:$E,D9_어깨팔B!$C:$C,$A7) -> 13 | C7: =MROUND(SUMIFS(간접계수맵!$F$7:$F$80,간접계수맵!$C$7:$C$80,$A7),0.5) -> 4 | D7: =B7+C7 -> 17 | E7: =IF(J7>20,"상한",IF(J7>=10,"성장",IF(J7>=8,"유지",IF(J7>=1,"유지 미만","미배치")))) -> 성장 | F7: 직접 12세트: 1일차 친업 4 · 랫풀다운 4 · 6일차 시티드 케이블 로우 4(좁은 그립). 간접은 넓은 그립 로우 2종(바벨 로우 · 해머 로우) 각 0.5 — 2026-09-04에 주동근을 능형·중부승모로 옮기며 협력근으로 내려왔다. 데드리프트의 광배 등척성은 0. | G7: 등 | H7: =SUM(D7:D10) -> 56.5 | J7: =ROUND(D7*7/$H$2,1) -> 11.9 | L7: =ROUND(B7*7/$H$2,1) -> 9.1
